Workbook

Sheet Description
D3: Lab-Book
H5: Supervisor: | I5: Johann F. Osma
B8: Experiment Nº: | C8: 10 | H8: Researcher: | I8: Ailin Prado Falla
B9: Title: | C9: Caracterization of microfluidic for samples of potenciostat sensor. | H9: Starting Date:
B11: Observations
B12: The objective of this experiment is to functionalize and measure the assembling of the newly developed lacase biosensor designed for a microfluidic system potentiostat. This was made remotly using four syringe pumps controled with an arduino uno. The measurements were made in a commertial potentiostat for 4 biosensors.
B20: Follow up of the experimentation
B21: Date | C21: Description | G21: Stage | I21: Location
C23: Biosensor 1 Voltamperogram water after aptes
C24: Biosensor 1 Voltamperogram water after glutaraldehyde
C25: Biosensor 1 Voltamperogram water after Laccase
C26: Biosensor 2 Voltamperogram water after aptes
C27: Biosensor 2 Voltamperogram water after glutaraldehyde
C28: Biosensor 2 Voltamperogram water after Laccase
C29: Biosensor 3 Voltamperogram water after aptes
C30: Biosensor 3 Voltamperogram water after glutaraldehyde
C31: Biosensor 3 Voltamperogram water after Laccase
C32: Biosensor 4 Voltamperogram water after aptes
C33: Biosensor 4 Voltamperogram water after glutaraldehyde
C34: Biosensor 4 Voltamperogram water after Laccase
C35: Voltamperogram Average
B39: Sample numbering/codification
B42: List of Reagents and/or materials
B43: Name of Reagent or material | E43: Provider | G43: Lot number | I43: Approx. Quantity | K43: Date
B45: Lab book | E45: Biomicrosystems | I45: 1 | K45: 45206
B46: Potenciostat | E46: Biomicrosystems | I46: 1 | K46: 45206
B47: Potenciostat | E47: Biomicrosystems | I47: 1 | K47: 45206
B48: MilliQ | E48: Biomicrosystems | I48: 1ml | K48: 45206
B49: Aptes | I49: 1ml | K49: 45213
B50: Glutaraldehyde | I50: 1ml | K50: 45213
B51: Laccase | I51: 1ml | K51: 45206

Sheet Biosensor1_Aptes
D3: Lab-Book
H5: Supervisor: | I5: Johann F. Osma
B8: Experiment Nº: | C8: =1 -> 1 | H8: Researcher: | I8: =Description!I8 -> Ailin Prado Falla
B9: Title: | C9: CV measurement of Aptes assembling in Biosensor 1. | H9: Starting Date: | I9: 45505
B11: Description of the experiment
B13: CV measurement of Aptes assembling in Biosensor 1 using remotly controlled syringe pumps.
B20: Measurement: | V20: Calculation and/or formula:
B21: Date | C21: Description | E21: Description | G21: Description | I21: Description | K21: Description | M21: Description | O21: Description | Q21: Description | S21: Description | V21: Date | W21: BioS1 | X21: BioS1 | Y21: BioS1
C22: Voltage (V) | D22: Current (µA) | E22: Voltage (V) | F22: Current (µA) | G22: Voltage (V) | H22: Current (µA) | I22: Voltage (V) | J22: Current (µA) | K22: Voltage (V) | L22: Current (µA) | M22: Voltage (V) | N22: Current (µA) | O22: Voltage (V) | P22: Current (µA) | Q22: Voltage (V) | R22: Current (µA) | S22: Voltage (V) | T22: Current (µA) | W22: Bio-APTES | X22: Bio-Glut | Y22: Bio-Lac | Z22: Sample 4 | AA22: Sample 5 | AB22: Sample 6 | AC22: Sample 7 | AD22: Sample 8 | AE22: Sample 9
B23: 45505 | C23: 7.6785371e-05 | D23: 42.618513 | E23: 7.6785371e-05 | F23: 0.52739763 | G23: 7.6785371e-05 | H23: 0.39116502 | I23: 7.6785371e-05 | J23: 0.3409934 | K23: 7.6785371e-05 | L23: 0.30016017 | M23: 7.6785371e-05 | N23: 2.8750286 | O23: 7.6785371e-05 | P23: 0.26381779 | Q23: 7.6785371e-05 | R23: 0.26603341 | S23: 7.6785371e-05 | T23: 0.25600825 | W23: =AVERAGE(J23,L23,N23,P23,R23,T23) -> 0.71700694 | X23: =Biosensor1_Glut!W23 -> 0.70302892 | Y23: =Biosensor1_Lacasa!Y23 -> 1.592813
B24: 45505 | C24: 0.010058884 | D24: 42.893171 | E24: 0.010058884 | F24: 0.56612492 | G24: 0.010058884 | H24: 0.42000461 | I24: 0.010058884 | J24: 0.36937523 | K24: 0.010058884 | L24: 0.32954907 | M24: 0.010058884 | N24: 0.31380177 | O24: 0.010058884 | P24: 0.29342642 | Q24: 0.010058884 | R24: 0.29431448 | S24: 0.010058884 | T24: 0.28606549 | W24: =AVERAGE(J24,L24,N24,P24,R24,T24) -> 0.31442208 | X24: =Biosensor1_Glut!W24 -> 0.7762417 | Y24: =Biosensor1_Lacasa!Y24 -> 1.6720989
B25: 45505 | C25: 0.020041382 | D25: 43.16783 | E25: 0.020041382 | F25: 0.60714126 | G25: 0.020041382 | H25: 0.44994283 | I25: 0.020041382 | J25: 0.39967966 | K25: 0.020041382 | L25: 0.3561914 | M25: 0.020041382 | N25: 0.34291601 | O25: 0.020041382 | P25: 0.32048535 | Q25: 0.020041382 | R25: 0.32021046 | S25: 0.020041382 | T25: 0.3131609 | W25: =AVERAGE(J25,L25,N25,P25,R25,T25) -> 0.3421073 | X25: =Biosensor1_Glut!W25 -> 0.84907305 | Y25: =Biosensor1_Lacasa!Y25 -> 1.8204165
B26: 45505 | C26: 0.03002348 | D26: 43.259382 | E26: 0.03002348 | F26: 0.64650941 | G26: 0.03002348 | H26: 0.48180366 | I26: 0.03002348 | J26: 0.42796969 | K26: 0.03002348 | L26: 0.38173485 | M26: 0.03002348 | N26: 0.37111473 | O26: 0.03002348 | P26: 0.35024023 | Q26: 0.03002348 | R26: 0.34978247 | S26: 0.03002348 | T26: 0.3441062 | W26: =AVERAGE(J26,L26,N26,P26,R26,T26) -> 0.37082469 | X26: =Biosensor1_Glut!W26 -> 0.92410163 | Y26: =Biosensor1_Lacasa!Y26 -> 2.0160219
B27: 45505 | C27: 0.040005978 | D27: 43.259382 | E27: 0.040005978 | F27: 0.67287707 | G27: 0.040005978 | H27: 0.51311517 | I27: 0.040005978 | J27: 0.4556191 | K27: 0.040005978 | L27: 0.40718699 | M27: 0.040005978 | N27: 0.39766526 | O27: 0.040005978 | P27: 0.3785305 | Q27: 0.040005978 | R27: 0.37825584 | S27: 0.040005978 | T27: 0.37303734 | W27: =AVERAGE(J27,L27,N27,P27,R27,T27) -> 0.3983825 | X27: =Biosensor1_Glut!W27 -> 1.0001831 | Y27: =Biosensor1_Lacasa!Y27 -> 2.2185398
B28: 45505 | C28: 0.049988076 | D28: 43.350935 | E28: 0.049988076 | F28: 0.71197081 | G28: 0.049988076 | H28: 0.5434196 | I28: 0.049988076 | J28: 0.48281074 | K28: 0.049988076 | L28: 0.43291378 | M28: 0.049988076 | N28: 0.42247653 | O28: 0.049988076 | P28: 0.40663767 | Q28: 0.049988076 | R28: 0.40645456 | S28: 0.049988076 | T28: 0.40224314 | W28: =AVERAGE(J28,L28,N28,P28,R28,T28) -> 0.4255894 | X28: =Biosensor1_Glut!W28 -> 1.078874 | Y28: =Biosensor1_Lacasa!Y28 -> 2.4199588
B29: 45505 | C29: 0.059970174 | D29: 43.373823 | E29: 0.059970174 | F29: 0.74996567 | G29: 0.059970174 | H29: 0.57473111 | I29: 0.059970174 | J29: 0.50991082 | K29: 0.059970174 | L29: 0.458915 | M29: 0.059970174 | N29: 0.44664693 | O29: 0.059970174 | P29: 0.43291378 | Q29: 0.059970174 | R29: 0.43456173 | S29: 0.059970174 | T29: 0.43044186 | W29: =AVERAGE(J29,L29,N29,P29,R29,T29) -> 0.45223169 | X29: =Biosensor1_Glut!W29 -> 1.1584344 | Y29: =Biosensor1_Lacasa!Y29 -> 2.6089573
B30: 45505 | C30: 0.069952674 | D30: 43.442488 | E30: 0.069952674 | F30: 0.7906158 | G30: 0.069952674 | H30: 0.60521865 | I30: 0.069952674 | J30: 0.53691912 | K30: 0.069952674 | L30: 0.48464179 | M30: 0.069952674 | N30: 0.4727397 | O30: 0.069952674 | P30: 0.45745015 | Q30: 0.069952674 | R30: 0.46257734 | S30: 0.069952674 | T30: 0.45772481 | W30: =AVERAGE(J30,L30,N30,P30,R30,T30) -> 0.47867548 | X30: =Biosensor1_Glut!W30 -> 1.2408484 | Y30: =Biosensor1_Lacasa!Y30 -> 2.7977187
B31: 45505 | C31: 0.079934768 | D31: 43.442488 | E31: 0.079934768 | F31: 0.82769513 | G31: 0.079934768 | H31: 0.63598084 | I31: 0.079934768 | J31: 0.56319523 | K31: 0.079934768 | L31: 0.51055169 | M31: 0.079934768 | N31: 0.4986496 | O31: 0.079934768 | P31: 0.48290229 | Q31: 0.079934768 | R31: 0.49095893 | S31: 0.079934768 | T31: 0.4832685 | W31: =AVERAGE(J31,L31,N31,P31,R31,T31) -> 0.50492104 | X31: =Biosensor1_Glut!W31 -> 1.325719 | Y31: =Biosensor1_Lacasa!Y31 -> 2.9827265
B32: 45505 | C32: 0.08991687 | D32: 43.484819 | E32: 0.08991687 | F32: 0.8660562 | G32: 0.08991687 | H32: 0.66674304 | I32: 0.08991687 | J32: 0.58883047 | K32: 0.08991687 | L32: 0.53719378 | M32: 0.08991687 | N32: 0.52355242 | O32: 0.08991687 | P32: 0.50872064 | Q32: 0.08991687 | R32: 0.51915765 | S32: 0.08991687 | T32: 0.50734711 | W32: =AVERAGE(J32,L32,N32,P32,R32,T32) -> 0.53080034 | X32: =Biosensor1_Glut!W32 -> 1.4117342 | Y32: =Biosensor1_Lacasa!Y32 -> 3.1617683
B33: 45505 | C33: 0.099899366 | D33: 43.53404 | E33: 0.099899366 | F33: 0.89919901 | G33: 0.099899366 | H33: 0.6964066 | I33: 0.099899366 | J33: 0.61455703 | K33: 0.099899366 | L33: 0.56346989 | M33: 0.099899366 | N33: 0.55010295 | O33: 0.099899366 | P33: 0.5346303 | Q33: 0.099899366 | R33: 0.54744792 | S33: 0.099899366 | T33: 0.53389788 | W33: =AVERAGE(J33,L33,N33,P33,R33,T33) -> 0.55735099 | X33: =Biosensor1_Glut!W33 -> 1.4983292 | Y33: =Biosensor1_Lacasa!Y33 -> 3.3389558
B34: 45505 | C34: 0.10988147 | D34: 43.52026 | E34: 0.10988147 | F34: 0.93408108 | G34: 0.10988147 | H34: 0.72671103 | I34: 0.10988147 | J34: 0.63643861 | K34: 0.10988147 | L34: 0.58919668 | M34: 0.10988147 | N34: 0.5761044 | O34: 0.10988147 | P34: 0.56136417 | Q34: 0.10988147 | R34: 0.57482266 | S34: 0.10988147 | T34: 0.56081486 | W34: =AVERAGE(J34,L34,N34,P34,R34,T34) -> 0.58312356 | X34: =Biosensor1_Glut!W34 -> 1.5842832 | Y34: =Biosensor1_Lacasa!Y34 -> 3.5075915
... B303: 45505 | C303: 7.6785371e-05 | D303: 0.52739763 | E303: 7.6785371e-05 | F303: 0.39116502 | G303: 7.6785371e-05 | H303: 0.3409934 | I303: 7.6785371e-05 | J303: 0.30016017 | K303: 7.6785371e-05 | L303: 0.28750287 | M303: 7.6785371e-05 | N303: 0.26381779 | O303: 7.6785371e-05 | P303: 0.26603341 | Q303: 7.6785371e-05 | R303: 0.25600825 | S303: 7.6785371e-05 | T303: 0.24107576 | W303: =AVERAGE(J303,L303,N303,P303,R303,T303) -> 0.26909971 | X303: =Biosensor1_Glut!W303 -> 0.69214924 | Y303: =Biosensor1_Lacasa!Y303 -> 1.7752651
V307: Summary of results
V309: Add in here average values, tables, figures or any result you've got

Sheet Biosensor1_Glut
D3: Lab-Book
H5: Supervisor: | I5: Johann F. Osma
B8: Experiment Nº: | C8: 2 | H8: Researcher: | I8: =Description!I8 -> Ailin Prado Falla
B9: Title: | C9: CV measurement of Glutaraldehyde assembling in Biosensor 1.
B11: Description of the experiment
B13: CV measurement of Glutaraldehyde assembling in Biosensor 1 using remotly controlled syringe pumps.
B20: Measurement: | V20: Calculation and/or formula:
B21: Date | C21: Description | E21: Description | G21: Description | I21: Description | K21: Description | M21: Description | O21: Description | Q21: Description | S21: Description | V21: Date | W21: Description
C22: Voltage (V) | D22: Current (µA) | E22: Voltage (V) | F22: Current (µA) | G22: Voltage (V) | H22: Current (µA) | I22: Voltage (V) | J22: Current (µA) | K22: Voltage (V) | L22: Current (µA) | M22: Voltage (V) | N22: Current (µA) | O22: Voltage (V) | P22: Current (µA) | Q22: Voltage (V) | R22: Current (µA) | S22: Voltage (V) | T22: Current (µA) | W22: Sample 1 | X22: Sample 2 | Y22: Sample 3 | Z22: Sample 4 | AA22: Sample 5 | AB22: Sample 6 | AC22: Sample 7 | AD22: Sample 8 | AE22: Sample 9
B23: 45505 | C23: 7.6785371e-05 | D23: 0.045776367 | E23: 7.6785371e-05 | F23: 0.50789666 | G23: 7.6785371e-05 | H23: 0.65575647 | I23: 7.6785371e-05 | J23: 0.70840001 | K23: 7.6785371e-05 | L23: 0.72304869 | M23: 7.6785371e-05 | N23: 0.72872519 | O23: 7.6785371e-05 | P23: 0.70684361 | Q23: 7.6785371e-05 | R23: 0.68523693 | S23: 7.6785371e-05 | T23: 0.66591907 | W23: =AVERAGE(J23,L23,N23,P23,R23,T23) -> 0.70302892
B24: 45505 | C24: 0.010058884 | D24: 0.045776367 | E24: 0.010058884 | F24: 0.56099796 | G24: 0.010058884 | H24: 0.7216754 | I24: 0.010058884 | J24: 0.78109407 | K24: 0.010058884 | L24: 0.79528499 | M24: 0.010058884 | N24: 0.80361629 | O24: 0.010058884 | P24: 0.78072786 | Q24: 0.010058884 | R24: 0.7582972 | S24: 0.010058884 | T24: 0.73842978 | W24: =AVERAGE(J24,L24,N24,P24,R24,T24) -> 0.7762417
B25: 45505 | C25: 0.020041382 | D25: 0.1373291 | E25: 0.020041382 | F25: 0.61492324 | G25: 0.020041382 | H25: 0.78924251 | I25: 0.020041382 | J25: 0.85442901 | K25: 0.020041382 | L25: 0.86944389 | M25: 0.020041382 | N25: 0.87997246 | O25: 0.020041382 | P25: 0.85452056 | Q25: 0.020041382 | R25: 0.82531476 | S25: 0.020041382 | T25: 0.81075764 | W25: =AVERAGE(J25,L25,N25,P25,R25,T25) -> 0.84907305
B26: 45505 | C26: 0.03002348 | D26: 0.1373291 | E26: 0.03002348 | F26: 0.66912341 | G26: 0.03002348 | H26: 0.85973907 | I26: 0.03002348 | J26: 0.9299612 | K26: 0.03002348 | L26: 0.94506741 | M26: 0.03002348 | N26: 0.95724416 | O26: 0.03002348 | P26: 0.92904544 | Q26: 0.03002348 | R26: 0.89892435 | S26: 0.03002348 | T26: 0.88436723 | W26: =AVERAGE(J26,L26,N26,P26,R26,T26) -> 0.92410163
B27: 45505 | C27: 0.040005978 | D27: 0.22888184 | E27: 0.040005978 | F27: 0.72442198 | G27: 0.040005978 | H27: 0.93243313 | I27: 0.040005978 | J27: 1.0094299 | K27: 0.040005978 | L27: 1.0219731 | M27: 0.040005978 | N27: 1.0352483 | O27: 0.040005978 | P27: 1.0024719 | Q27: 0.040005978 | R27: 0.97308302 | S27: 0.040005978 | T27: 0.95889211 | W27: =AVERAGE(J27,L27,N27,P27,R27,T27) -> 1.0001831
B28: 45505 | C28: 0.049988076 | D28: 0.23345947 | E28: 0.049988076 | F28: 0.78054476 | G28: 0.049988076 | H28: 1.0070496 | I28: 0.049988076 | J28: 1.0927444 | K28: 0.049988076 | L28: 1.100801 | M28: 0.049988076 | N28: 1.1160908 | O28: 0.049988076 | P28: 1.0795608 | Q28: 0.049988076 | R28: 1.0498056 | S28: 0.049988076 | T28: 1.0342412 | W28: =AVERAGE(J28,L28,N28,P28,R28,T28) -> 1.078874
B29: 45505 | C29: 0.059970174 | D29: 0.27923584 | E29: 0.059970174 | F29: 0.83739996 | G29: 0.059970174 | H29: 1.0845046 | I29: 0.059970174 | J29: 1.176425 | K29: 0.059970174 | L29: 1.1821928 | M29: 0.059970174 | N29: 1.1966581 | O29: 0.059970174 | P29: 1.1595788 | Q29: 0.059970174 | R29: 1.1275349 | S29: 0.059970174 | T29: 1.1082168 | W29: =AVERAGE(J29,L29,N29,P29,R29,T29) -> 1.1584344
B30: 45505 | C30: 0.069952674 | D30: 0.32501221 | E30: 0.069952674 | F30: 0.89498734 | G30: 0.069952674 | H30: 1.164248 | I30: 0.069952674 | J30: 1.2631264 | K30: 0.069952674 | L30: 1.2653236 | M30: 0.069952674 | N30: 1.2801557 | O30: 0.069952674 | P30: 1.2405128 | Q30: 0.069952674 | R30: 1.206821 | S30: 0.069952674 | T30: 1.1891508 | W30: =AVERAGE(J30,L30,N30,P30,R30,T30) -> 1.2408484
B31: 45505 | C31: 0.079934768 | D31: 0.37078857 | E31: 0.079934768 | F31: 0.95284963 | G31: 0.079934768 | H31: 1.2480202 | I31: 0.079934768 | J31: 1.3516593 | K31: 0.079934768 | L31: 1.3501029 | M31: 0.079934768 | N31: 1.3679562 | O31: 0.079934768 | P31: 1.3247423 | Q31: 0.079934768 | R31: 1.2871137 | S31: 0.079934768 | T31: 1.2727399 | W31: =AVERAGE(J31,L31,N31,P31,R31,T31) -> 1.325719
B32: 45505 | C32: 0.08991687 | D32: 0.41656494 | E32: 0.08991687 | F32: 1.0130005 | G32: 0.08991687 | H32: 1.3350883 | I32: 0.08991687 | J32: 1.4407415 | K32: 0.08991687 | L32: 1.4342413 | M32: 0.08991687 | N32: 1.4579539 | O32: 0.08991687 | P32: 1.4106202 | Q32: 0.08991687 | R32: 1.3704281 | S32: 0.08991687 | T32: 1.35642 | W32: =AVERAGE(J32,L32,N32,P32,R32,T32) -> 1.4117342
B33: 45505 | C33: 0.099899366 | D33: 0.46738386 | E33: 0.099899366 | F33: 1.0743418 | G33: 0.099899366 | H33: 1.4249945 | I33: 0.099899366 | J33: 1.5295491 | K33: 0.099899366 | L33: 1.5187459 | M33: 0.099899366 | N33: 1.5461202 | O33: 0.099899366 | P33: 1.4965897 | Q33: 0.099899366 | R33: 1.4574046 | S33: 0.099899366 | T33: 1.4415655 | W33: =AVERAGE(J33,L33,N33,P33,R33,T33) -> 1.4983292
B34: 45505 | C34: 0.10988147 | D34: 0.51590681 | E34: 0.10988147 | F34: 1.137331 | G34: 0.10988147 | H34: 1.5159078 | I34: 0.10988147 | J34: 1.6168919 | K34: 0.10988147 | L34: 1.6049895 | M34: 0.10988147 | N34: 1.6317234 | O34: 0.10988147 | P34: 1.5833831 | Q34: 0.10988147 | R34: 1.5430074 | S34: 0.10988147 | T34: 1.5257039 | W34: =AVERAGE(J34,L34,N34,P34,R34,T34) -> 1.5842832
... B303: 45505 | C303: 7.6785371e-05 | D303: 0.50789666 | E303: 7.6785371e-05 | F303: 0.65575647 | G303: 7.6785371e-05 | H303: 0.70840001 | I303: 7.6785371e-05 | J303: 0.72304869 | K303: 7.6785371e-05 | L303: 0.72872519 | M303: 7.6785371e-05 | N303: 0.70684361 | O303: 7.6785371e-05 | P303: 0.68523693 | Q303: 7.6785371e-05 | R303: 0.66591907 | S303: 7.6785371e-05 | T303: 0.64312196 | W303: =AVERAGE(J303,L303,N303,P303,R303,T303) -> 0.69214924
V306: Summary of results
V308: Add in here average values, tables, figures or any result you've got

Sheet Biosensor1_Lacasa
D3: Lab-Book
H5: Supervisor: | I5: Johann F. Osma
B8: Experiment Nº: | C8: 3 | H8: Researcher: | I8: =Description!I8 -> Ailin Prado Falla
B9: Title: | C9: CV measurement of Laccase assembling in Biosensor 1.
B11: Description of the experiment
B13: CV measurement of Laccase assembling in Biosensor 1 using remotly controlled syringe pumps.
B20: Measurement: | X20: Calculation and/or formula:
B21: Date | C21: Description | E21: Description | G21: Description | I21: Description | K21: Description | M21: Description | O21: Description | Q21: Description | S21: Description | X21: Date | Y21: Description
C22: Voltage (V) | D22: Current (µA) | E22: Voltage (V) | F22: Current (µA) | G22: Voltage (V) | H22: Current (µA) | I22: Voltage (V) | J22: Current (µA) | K22: Voltage (V) | L22: Current (µA) | M22: Voltage (V) | N22: Current (µA) | O22: Voltage (V) | P22: Current (µA) | Q22: Voltage (V) | R22: Current (µA) | S22: Voltage (V) | T22: Current (µA) | Y22: Sample 1 | Z22: Sample 2 | AA22: Sample 3 | AB22: Sample 4 | AC22: Sample 5 | AD22: Sample 6 | AE22: Sample 7 | AF22: Sample 8 | AG22: Sample 9
B23: 45505 | C23: 7.6785371e-05 | D23: -0.045776367 | E23: 7.6785371e-05 | F23: 0.12986946 | G23: 7.6785371e-05 | H23: 0.58013272 | I23: 7.6785371e-05 | J23: 0.92721438 | K23: 7.6785371e-05 | L23: 1.0662851 | M23: 7.6785371e-05 | N23: 1.3127489 | O23: 7.6785371e-05 | P23: 1.8414741 | Q23: 7.6785371e-05 | R23: 2.1577935 | S23: 7.6785371e-05 | T23: 2.2513618 | Y23: =AVERAGE(J23,L23,N23,P23,R23,T23) -> 1.592813
B24: 45505 | C24: 0.010058884 | D24: 0.045776367 | E24: 0.010058884 | F24: 0.30199122 | G24: 0.010058884 | H24: 0.75747299 | I24: 0.010058884 | J24: 1.1246967 | K24: 0.010058884 | L24: 1.2866559 | M24: 0.010058884 | N24: 1.5401692 | O24: 0.010058884 | P24: 1.8367133 | Q24: 0.010058884 | R24: 2.0703592 | S24: 0.010058884 | T24: 2.1739988 | Y24: =AVERAGE(J24,L24,N24,P24,R24,T24) -> 1.6720989
B25: 45505 | C25: 0.020041382 | D25: 0.22888184 | E25: 0.020041382 | F25: 0.4744792 | G25: 0.020041382 | H25: 0.93444729 | I25: 0.020041382 | J25: 1.3202562 | K25: 0.020041382 | L25: 1.503273 | M25: 0.020041382 | N25: 1.7626457 | O25: 0.020041382 | P25: 2.0035248 | Q25: 0.020041382 | R25: 2.1325245 | S25: 0.020041382 | T25: 2.2002745 | Y25: =AVERAGE(J25,L25,N25,P25,R25,T25) -> 1.8204165
B26: 45505 | C26: 0.03002348 | D26: 0.32043457 | E26: 0.03002348 | F26: 0.64705873 | G26: 0.03002348 | H26: 1.1082168 | I26: 0.03002348 | J26: 1.5132523 | K26: 0.03002348 | L26: 1.7159534 | M26: 0.03002348 | N26: 1.9802699 | O26: 0.03002348 | P26: 2.1983519 | Q26: 0.03002348 | R26: 2.3156328 | S26: 0.03002348 | T26: 2.3726711 | Y26: =AVERAGE(J26,L26,N26,P26,R26,T26) -> 2.0160219
B27: 45505 | C27: 0.040005978 | D27: 0.50354004 | E27: 0.040005978 | F27: 0.81652546 | G27: 0.040005978 | H27: 1.2822614 | I27: 0.040005978 | J27: 1.7079883 | K27: 0.040005978 | L27: 1.9246969 | M27: 0.040005978 | N27: 2.1927671 | O27: 0.040005978 | P27: 2.3983979 | Q27: 0.040005978 | R27: 2.5197988 | S27: 0.040005978 | T27: 2.5675898 | Y27: =AVERAGE(J27,L27,N27,P27,R27,T27) -> 2.2185398
B28: 45505 | C28: 0.049988076 | D28: 0.66375732 | E28: 0.049988076 | F28: 0.98626685 | G28: 0.049988076 | H28: 1.4573131 | I28: 0.049988076 | J28: 1.8972306 | K28: 0.049988076 | L28: 2.1282215 | M28: 0.049988076 | N28: 2.4016023 | O28: 0.049988076 | P28: 2.600183 | Q28: 0.049988076 | R28: 2.7238727 | S28: 0.049988076 | T28: 2.7686429 | Y28: =AVERAGE(J28,L28,N28,P28,R28,T28) -> 2.4199588
B29: 45505 | C29: 0.059970174 | D29: 0.87435246 | E29: 0.059970174 | F29: 1.1540856 | G29: 0.059970174 | H29: 1.6341038 | I29: 0.059970174 | J29: 2.0815291 | K29: 0.059970174 | L29: 2.3236895 | M29: 0.059970174 | N29: 2.6019225 | O29: 0.059970174 | P29: 2.7990389 | Q29: 0.059970174 | R29: 2.9054713 | S29: 0.059970174 | T29: 2.9420924 | Y29: =AVERAGE(J29,L29,N29,P29,R29,T29) -> 2.6089573
B30: 45505 | C30: 0.069952674 | D30: 1.0849237 | E30: 0.069952674 | F30: 1.3235521 | G30: 0.069952674 | H30: 1.8103456 | I30: 0.069952674 | J30: 2.2655525 | K30: 0.069952674 | L30: 2.5129318 | M30: 0.069952674 | N30: 2.7951932 | O30: 0.069952674 | P30: 2.9787135 | Q30: 0.069952674 | R30: 3.0968189 | S30: 0.069952674 | T30: 3.1371021 | Y30: =AVERAGE(J30,L30,N30,P30,R30,T30) -> 2.7977187
B31: 45505 | C31: 0.079934768 | D31: 1.3046503 | E31: 0.079934768 | F31: 1.5018082 | G31: 0.079934768 | H31: 1.984848 | I31: 0.079934768 | J31: 2.4482031 | K31: 0.079934768 | L31: 2.6955824 | M31: 0.079934768 | N31: 2.9677272 | O31: 0.079934768 | P31: 3.1654835 | Q31: 0.079934768 | R31: 3.2845044 | S31: 0.079934768 | T31: 3.3348584 | Y31: =AVERAGE(J31,L31,N31,P31,R31,T31) -> 2.9827265
B32: 45505 | C32: 0.08991687 | D32: 1.5243769 | E32: 0.08991687 | F32: 1.6867476 | G32: 0.08991687 | H32: 2.1609063 | I32: 0.08991687 | J32: 2.6259098 | K32: 0.08991687 | L32: 2.8578615 | M32: 0.08991687 | N32: 3.150835 | O32: 0.08991687 | P32: 3.3458447 | Q32: 0.08991687 | R32: 3.4694433 | S32: 0.08991687 | T32: 3.5207152 | Y32: =AVERAGE(J32,L32,N32,P32,R32,T32) -> 3.1617683
B33: 45505 | C33: 0.099899366 | D33: 1.7198443 | E33: 0.099899366 | F33: 1.8722363 | G33: 0.099899366 | H33: 2.3370566 | I33: 0.099899366 | J33: 2.8037081 | K33: 0.099899366 | L33: 3.0290675 | M33: 0.099899366 | N33: 3.3266187 | O33: 0.099899366 | P33: 3.5143042 | Q33: 0.099899366 | R33: 3.6552978 | S33: 0.099899366 | T33: 3.7047386 | Y33: =AVERAGE(J33,L33,N33,P33,R33,T33) -> 3.3389558
B34: 45505 | C34: 0.10988147 | D34: 1.9276714 | E34: 0.10988147 | F34: 2.0543375 | G34: 0.10988147 | H34: 2.5156784 | I34: 0.10988147 | J34: 2.9613185 | K34: 0.10988147 | L34: 3.199358 | M34: 0.10988147 | N34: 3.4996557 | O34: 0.10988147 | P34: 3.6763573 | Q34: 0.10988147 | R34: 3.8310838 | S34: 0.10988147 | T34: 3.8777757 | Y34: =AVERAGE(J34,L34,N34,P34,R34,T34) -> 3.5075915
... B303: 45505 | C303: 7.6785371e-05 | D303: 0.12986946 | E303: 7.6785371e-05 | F303: 0.58013272 | G303: 7.6785371e-05 | H303: 0.92721438 | I303: 7.6785371e-05 | J303: 1.0662851 | K303: 7.6785371e-05 | L303: 1.3127489 | M303: 7.6785371e-05 | N303: 1.8414741 | O303: 7.6785371e-05 | P303: 2.1577935 | Q303: 7.6785371e-05 | R303: 2.2513618 | S303: 7.6785371e-05 | T303: 2.0219274 | Y303: =AVERAGE(J303,L303,N303,P303,R303,T303) -> 1.7752651
Y304: =AVERAGE(J304,L304,N304,P304,R304,T304) -> #DIV/0!
Y305: =AVERAGE(J305,L305,N305,P305,R305,T305) -> #DIV/0!
Y306: =AVERAGE(J306,L306,N306,P306,R306,T306) -> #DIV/0!
Y307: =AVERAGE(J307,L307,N307,P307,R307,T307) -> #DIV/0!
Y308: =AVERAGE(J308,L308,N308,P308,R308,T308) -> #DIV/0!
Y309: =AVERAGE(J309,L309,N309,P309,R309,T309) -> #DIV/0!
Y310: =AVERAGE(J310,L310,N310,P310,R310,T310) -> #DIV/0!
Y311: =AVERAGE(J311,L311,N311,P311,R311,T311) -> #DIV/0!
Y312: =AVERAGE(J312,L312,N312,P312,R312,T312) -> #DIV/0!
Y313: =AVERAGE(J313,L313,N313,P313,R313,T313) -> #DIV/0!
Y314: =AVERAGE(J314,L314,N314,P314,R314,T314) -> #DIV/0!
Y315: =AVERAGE(J315,L315,N315,P315,R315,T315) -> #DIV/0!
... Y423: =AVERAGE(J423,L423,N423,P423,R423,T423) -> #DIV/0!
X425: Summary of results
X427: Add in here average values, tables, figures or any result you've got

Sheet Biosensor2_Aptes
D3: Lab-Book
H5: Supervisor: | I5: Johann F. Osma
B8: Experiment Nº: | C8: 4 | H8: Researcher: | I8: =Description!I8 -> Ailin Prado Falla
B9: Title: | C9: CV measurement of Aptes assembling in Biosensor 2. | H9: Starting Date: | I9: 45505
B11: Description of the experiment
B13: CV measurement of Aptes assembling in Biosensor 2 using remotly controlled syringe pumps.
B20: Measurement: | V20: Calculation and/or formula:
B21: Date | C21: Description | E21: Description | G21: Description | I21: Description | K21: Description | M21: Description | O21: Description | Q21: Description | S21: Description | V21: Date | W21: BioS2 | X21: BioS2 | Y21: BioS2
C22: Voltage (V) | D22: Current (µA) | E22: Voltage (V) | F22: Current (µA) | G22: Voltage (V) | H22: Current (µA) | I22: Voltage (V) | J22: Current (µA) | K22: Voltage (V) | L22: Current (µA) | M22: Voltage (V) | N22: Current (µA) | O22: Voltage (V) | P22: Current (µA) | Q22: Voltage (V) | R22: Current (µA) | S22: Voltage (V) | T22: Current (µA) | W22: Bio-APTES | X22: Bio-Glut | Y22: Bio-Lac | Z22: Sample 4 | AA22: Sample 5 | AB22: Sample 6 | AC22: Sample 7 | AD22: Sample 8 | AE22: Sample 9
B23: 45505 | C23: 7.6785371e-05 | D23: 0.045776367 | E23: 7.6785371e-05 | F23: 18.306255 | G23: 7.6785371e-05 | H23: 111.05976 | I23: 7.6785371e-05 | J23: 184.98516 | K23: 7.6785371e-05 | L23: 230.8538 | M23: 7.6785371e-05 | N23: 145.06745 | O23: 7.6785371e-05 | P23: 199.22638 | Q23: 7.6785371e-05 | R23: 223.89555 | S23: 7.6785371e-05 | T23: 238.04531 | W23: =AVERAGE(J23,L23,N23,P23,R23,T23) -> 203.67894 | X23: =Biosensor2_Glut!W23 -> 8.9295046 | Y23: =Biosensor2_Lacasa!W23 -> -0.76821844
B24: 45505 | C24: 0.010058884 | D24: 0.22888184 | E24: 0.010058884 | F24: 28.249025 | G24: 0.010058884 | H24: 136.65829 | I24: 0.010058884 | J24: 233.96659 | K24: 0.010058884 | L24: 296.86427 | M24: 0.010058884 | N24: 203.02129 | O24: 0.010058884 | P24: 251.03683 | Q24: 0.010058884 | R24: 301.0757 | S24: 0.010058884 | T24: 299.78027 | W24: =AVERAGE(J24,L24,N24,P24,R24,T24) -> 264.29083 | X24: =Biosensor2_Glut!W24 -> 10.934996 | Y24: =Biosensor2_Lacasa!W24 -> 10.868012
B25: 45505 | C25: 0.020041382 | D25: 0.4119873 | E25: 0.020041382 | F25: 41.368723 | G25: 0.020041382 | H25: 161.0117 | I25: 0.020041382 | J25: 280.47609 | K25: 0.020041382 | L25: 371.11473 | M25: 0.020041382 | N25: 263.44705 | O25: 0.020041382 | P25: 299.93591 | Q25: 0.020041382 | R25: 380.45311 | S25: 0.020041382 | T25: 356.28295 | W25: =AVERAGE(J25,L25,N25,P25,R25,T25) -> 325.28497 | X25: =Biosensor2_Glut!W25 -> 12.935302 | Y25: =Biosensor2_Lacasa!W25 -> 22.575954
B26: 45505 | C26: 0.03002348 | D26: 0.77819824 | E26: 0.03002348 | F26: 52.034783 | G26: 0.03002348 | H26: 184.94391 | I26: 0.03002348 | J26: 325.97852 | K26: 0.03002348 | L26: 442.25216 | M26: 0.03002348 | N26: 326.25318 | O26: 0.03002348 | P26: 358.93798 | Q26: 0.03002348 | R26: 451.31612 | S26: 0.03002348 | T26: 422.38498 | W26: =AVERAGE(J26,L26,N26,P26,R26,T26) -> 387.85382 | X26: =Biosensor2_Glut!W26 -> 14.980163 | Y26: =Biosensor2_Lacasa!W26 -> 34.432212
B27: 45505 | C27: 0.040005978 | D27: 2.1514893 | E27: 0.040005978 | F27: 62.389565 | G27: 0.040005978 | H27: 209.80086 | I27: 0.040005978 | J27: 369.00902 | K27: 0.040005978 | L27: 514.03069 | M27: 0.040005978 | N27: 387.41136 | O27: 0.040005978 | P27: 421.10324 | Q27: 0.040005978 | R27: 530.14421 | S27: 0.040005978 | T27: 498.8327 | W27: =AVERAGE(J27,L27,N27,P27,R27,T27) -> 453.42187 | X27: =Biosensor2_Glut!W27 -> 17.346991 | Y27: =Biosensor2_Lacasa!W27 -> 46.885864
B28: 45505 | C28: 0.049988076 | D28: 4.8294783 | E28: 0.049988076 | F28: 73.8796 | G28: 0.049988076 | H28: 229.6864 | I28: 0.049988076 | J28: 412.03928 | K28: 0.049988076 | L28: 583.52017 | M28: 0.049988076 | N28: 462.21113 | O28: 0.049988076 | P28: 482.62763 | Q28: 0.049988076 | R28: 620.05043 | S28: 0.049988076 | T28: 572.44229 | W28: =AVERAGE(J28,L28,N28,P28,R28,T28) -> 522.14849 | X28: =Biosensor2_Glut!W28 -> 19.655832 | Y28: =Biosensor2_Lacasa!W28 -> 60.321283
B29: 45505 | C29: 0.059970174 | D29: 6.8619728 | E29: 0.059970174 | F29: 85.644317 | G29: 0.059970174 | H29: 252.59328 | I29: 0.059970174 | J29: 456.53462 | K29: 0.059970174 | L29: 649.8971 | M29: 0.059970174 | N29: 526.48211 | O29: 0.059970174 | P29: 554.86393 | Q29: 0.059970174 | R29: 724.33043 | S29: 0.059970174 | T29: 654.56629 | W29: =AVERAGE(J29,L29,N29,P29,R29,T29) -> 594.44575 | X29: =Biosensor2_Glut!W29 -> 21.896466 | Y29: =Biosensor2_Lacasa!W29 -> 75.055542
B30: 45505 | C30: 0.069952674 | D30: 8.5923433 | E30: 0.069952674 | F30: 96.942091 | G30: 0.069952674 | H30: 273.87962 | I30: 0.069952674 | J30: 504.32587 | K30: 0.069952674 | L30: 716.54844 | M30: 0.069952674 | N30: 595.97158 | O30: 0.069952674 | P30: 622.70546 | Q30: 0.069952674 | R30: 823.48371 | S30: 0.069952674 | T30: 741.54258 | W30: =AVERAGE(J30,L30,N30,P30,R30,T30) -> 667.42961 | X30: =Biosensor2_Glut!W30 -> 23.992752 | Y30: =Biosensor2_Lacasa!W30 -> 90.675899
B31: 45505 | C31: 0.079934768 | D31: 10.093832 | E31: 0.079934768 | F31: 108.90822 | G31: 0.079934768 | H31: 297.04738 | I31: 0.079934768 | J31: 552.02556 | K31: 0.079934768 | L31: 784.20687 | M31: 0.079934768 | N31: 669.85583 | O31: 0.079934768 | P31: 691.00475 | Q31: 0.079934768 | R31: 915.58719 | S31: 0.079934768 | T31: 825.40631 | W31: =AVERAGE(J31,L31,N31,P31,R31,T31) -> 739.68108 | X31: =Biosensor2_Glut!W31 -> 27.135727 | Y31: =Biosensor2_Lacasa!W31 -> 106.63058
B32: 45505 | C32: 0.08991687 | D32: 11.604476 | E32: 0.08991687 | F32: 127.78668 | G32: 0.08991687 | H32: 320.94312 | I32: 0.08991687 | J32: 599.8168 | K32: 0.08991687 | L32: 854.15435 | M32: 0.08991687 | N32: 741.63413 | O32: 0.08991687 | P32: 760.31137 | Q32: 0.08991687 | R32: 1025.9099 | S32: 0.08991687 | T32: 893.15629 | W32: =AVERAGE(J32,L32,N32,P32,R32,T32) -> 812.49714 | X32: =Biosensor2_Glut!W32 -> 30.200045 | Y32: =Biosensor2_Lacasa!W32 -> 122.2723
B33: 45505 | C33: 0.099899366 | D33: 13.023567 | E33: 0.099899366 | F33: 139.13941 | G33: 0.099899366 | H33: 344.1062 | I33: 0.099899366 | J33: 645.41078 | K33: 0.099899366 | L33: 928.22146 | M33: 0.099899366 | N33: 813.04646 | O33: 0.099899366 | P33: 826.41339 | Q33: 0.099899366 | R33: 1131.8378 | S33: 0.099899366 | T33: 957.88503 | W33: =AVERAGE(J33,L33,N33,P33,R33,T33) -> 883.80249 | X33: =Biosensor2_Glut!W33 -> 33.570609 | Y33: =Biosensor2_Lacasa!W33 -> 138.04295
B34: 45505 | C34: 0.10988147 | D34: 13.563752 | E34: 0.10988147 | F34: 147.97435 | G34: 0.10988147 | H34: 367.72728 | I34: 0.10988147 | J34: 692.6527 | K34: 0.10988147 | L34: 996.7041 | M34: 0.10988147 | N34: 886.19828 | O34: 0.10988147 | P34: 899.38211 | Q34: 0.10988147 | R34: 1239.2311 | S34: 0.10988147 | T34: 1024.4451 | W34: =AVERAGE(J34,L34,N34,P34,R34,T34) -> 956.43556 | X34: =Biosensor2_Glut!W34 -> 36.84199 | Y34: =Biosensor2_Lacasa!W34 -> 154.40764
... B303: 45505 | C303: -0.79850304 | D303: -89.33394 | E303: -0.79850304 | F303: -939.75735 | G303: -0.79850304 | H303: -1993.1792 | I303: -0.79850304 | J303: -3047.3804 | K303: -0.79850304 | L303: -4506.7525 | M303: -0.79850304 | N303: -4260.4709 | O303: -0.79850304 | P303: -3405.3564 | Q303: -0.79850304 | R303: -3098.65 | S303: -0.79850304 | T303: -3864.9583 | W303: =AVERAGE(J303,L303,N303,P303,R303,T303) -> -3697.2614 | X303: =Biosensor2_Glut!W303 -> 10.291755 | Y303: =Biosensor2_Lacasa!W303 -> -2.3094455
C304: -0.80848557 | D304: -90.643167 | E304: -0.80848557 | F304: -951.65944 | G304: -0.80848557 | H304: -2002.1515 | I304: -0.80848557 | J304: -3041.8849 | K304: -0.80848557 | L304: -4531.4717 | M304: -0.80848557 | N304: -4243.9914 | O304: -0.80848557 | P304: -3338.5205 | Q304: -0.80848557 | R304: -3054.7047 | S304: -0.80848557 | T304: -3875.0291 | W304: =AVERAGE(J304,L304,N304,P304,R304,T304) -> -3680.9337
C305: -0.81846768 | D305: -90.917826 | E305: -0.81846768 | F305: -953.6736 | G305: -0.81846768 | H305: -2012.7718 | I305: -0.81846768 | J305: -3035.4762 | K305: -0.81846768 | L305: -4568.0928 | M305: -0.81846768 | N305: -4230.2585 | O305: -0.81846768 | P305: -3369.6508 | Q305: -0.81846768 | R305: -3338.5205 | S305: -0.81846768 | T305: -3859.4651 | W305: =AVERAGE(J305,L305,N305,P305,R305,T305) -> -3733.5773
C306: -0.82845014 | D306: -90.991068 | E306: -0.82845014 | F306: -955.87087 | G306: -0.82845014 | H306: -2009.4757 | I306: -0.82845014 | J306: -3038.2228 | K306: -0.82845014 | L306: -4545.2046 | M306: -0.82845014 | N306: -4210.1169 | O306: -0.82845014 | P306: -3289.0821 | Q306: -0.82845014 | R306: -3160.9058 | S306: -0.82845014 | T306: -3860.3806 | W306: =AVERAGE(J306,L306,N306,P306,R306,T306) -> -3683.9855
C307: -0.83843225 | D307: -91.329813 | E307: -0.83843225 | F307: -958.89211 | G307: -0.83843225 | H307: -2016.1593 | I307: -0.83843225 | J307: -3027.2365 | K307: -0.83843225 | L307: -4513.1612 | M307: -0.83843225 | N307: -4180.82 | O307: -0.83843225 | P307: -3227.7417 | Q307: -0.83843225 | R307: -3019.9122 | S307: -0.83843225 | T307: -3871.367 | W307: =AVERAGE(J307,L307,N307,P307,R307,T307) -> -3640.0398
C308: -0.84841436 | D308: -91.760135 | E308: -0.84841436 | F308: -956.78639 | G308: -0.84841436 | H308: -2015.3353 | I308: -0.84841436 | J308: -3027.2365 | K308: -0.84841436 | L308: -4510.4146 | M308: -0.84841436 | N308: -4137.7878 | O308: -0.84841436 | P308: -3141.6798 | Q308: -0.84841436 | R308: -2765.8504 | S308: -0.84841436 | T308: -3868.6204 | W308: =AVERAGE(J308,L308,N308,P308,R308,T308) -> -3575.2649
C309: -0.85839683 | D309: -92.144656 | E309: -0.85839683 | F309: -959.25832 | G309: -0.85839683 | H309: -2018.6542 | I309: -0.85839683 | J309: -3025.4054 | K309: -0.85839683 | L309: -4492.1041 | M309: -0.85839683 | N309: -4136.8723 | O309: -0.85839683 | P309: -3108.7208 | Q309: -0.85839683 | R309: -2739.4138 | S309: -0.85839683 | T309: -3837.4925 | W309: =AVERAGE(J309,L309,N309,P309,R309,T309) -> -3556.6681
C310: -0.86837894 | D310: -92.465091 | E310: -0.86837894 | F310: -959.07521 | G310: -0.86837894 | H310: -2021.7443 | I310: -0.86837894 | J310: -3023.5744 | K310: -0.86837894 | L310: -4487.5264 | M310: -0.86837894 | N310: -4083.7717 | O310: -0.86837894 | P310: -3052.8736 | Q310: -0.86837894 | R310: -2595.1028 | S310: -0.86837894 | T310: -3839.3235 | W310: =AVERAGE(J310,L310,N310,P310,R310,T310) -> -3513.6954
C311: -0.87836146 | D311: -93.298244 | E311: -0.87836146 | F311: -959.0981 | G311: -0.87836146 | H311: -2021.3778 | I311: -0.87836146 | J311: -3023.5744 | K311: -0.87836146 | L311: -4475.6246 | M311: -0.87836146 | N311: -4064.5456 | O311: -0.87836146 | P311: -3016.2501 | Q311: -0.87836146 | R311: -2576.7899 | S311: -0.87836146 | T311: -3795.1481 | W311: =AVERAGE(J311,L311,N311,P311,R311,T311) -> -3491.9888
C312: -0.88834357 | D312: -93.63699 | E312: -0.88834357 | F312: -958.89211 | G312: -0.88834357 | H312: -2018.2422 | I312: -0.88834357 | J312: -3021.7433 | K312: -0.88834357 | L312: -4460.9761 | M312: -0.88834357 | N312: -4064.5456 | O312: -0.88834357 | P312: -2989.6998 | Q312: -0.88834357 | R312: -2538.3377 | S312: -0.88834357 | T312: -3756.0081 | W312: =AVERAGE(J312,L312,N312,P312,R312,T312) -> -3471.8851
C313: -0.89832562 | D313: -93.682766 | E313: -0.89832562 | F313: -959.16677 | G313: -0.89832562 | H313: -2014.6945 | I313: -0.89832562 | J313: -3012.588 | K313: -0.89832562 | L313: -4446.3253 | M313: -0.89832562 | N313: -4060.6546 | O313: -0.89832562 | P313: -2942.0924 | Q313: -0.89832562 | R313: -2593.2717 | S313: -0.89832562 | T313: -3747.7684 | W313: =AVERAGE(J313,L313,N313,P313,R313,T313) -> -3467.1168
C314: -0.90830815 | D314: -94.250393 | E314: -0.90830815 | F314: -962.80611 | G314: -0.90830815 | H314: -2015.1522 | I314: -0.90830815 | J314: -3010.757 | K314: -0.90830815 | L314: -4413.3663 | M314: -0.90830815 | N314: -4055.3904 | O314: -0.90830815 | P314: -2858.777 | Q314: -0.90830815 | R314: -2520.0272 | S314: -0.90830815 | T314: -3640.421 | W314: =AVERAGE(J314,L314,N314,P314,R314,T314) -> -3416.4565
C315: -0.91829026 | D315: -94.589162 | E315: -0.91829026 | F315: -967.3152 | G315: -0.91829026 | H315: -2027.0543 | I315: -0.91829026 | J315: -3004.3483 | K315: -0.91829026 | L315: -4383.1539 | M315: -0.91829026 | N315: -4032.2161 | O315: -0.91829026 | P315: -2787.3659 | Q315: -0.91829026 | R315: -2828.5646 | S315: -0.91829026 | T315: -3501.4868 | W315: =AVERAGE(J315,L315,N315,P315,R315,T315) -> -3422.8559
... C423: 7.6785371e-05 | D423: 18.306255 | E423: 7.6785371e-05 | F423: 111.05976 | G423: 7.6785371e-05 | H423: 184.98516 | I423: 7.6785371e-05 | J423: 230.8538 | K423: 7.6785371e-05 | L423: 145.06745 | M423: 7.6785371e-05 | N423: 199.22638 | O423: 7.6785371e-05 | P423: 223.89555 | Q423: 7.6785371e-05 | R423: 238.04531 | S423: 7.6785371e-05 | T423: 99.107265 | W423: =AVERAGE(J423,L423,N423,P423,R423,T423) -> 189.36596
V425: Summary of results
V427: Add in here average values, tables, figures or any result you've got

Sheet Biosensor2_Glut
D3: Lab-Book
H5: Supervisor: | I5: Johann F. Osma
B8: Experiment Nº: | C8: 5 | H8: Researcher: | I8: =Description!I8 -> Ailin Prado Falla
B9: Title: | C9: CV measurement of Glutaraldehyde assembling in Biosensor 2.
B11: Description of the experiment
B13: CV measurement of Glutaraldehyde assembling in Biosensor 2 using remotly controlled syringe pumps.
B20: Measurement: | V20: Calculation and/or formula:
B21: Date | C21: Description | E21: Description | G21: Description | I21: Description | K21: Description | M21: Description | O21: Description | Q21: Description | S21: Description | V21: Date | W21: Description
C22: Voltage (V) | D22: Current (µA) | E22: Voltage (V) | F22: Current (µA) | G22: Voltage (V) | H22: Current (µA) | I22: Voltage (V) | J22: Current (µA) | K22: Voltage (V) | L22: Current (µA) | M22: Voltage (V) | N22: Current (µA) | O22: Voltage (V) | P22: Current (µA) | Q22: Voltage (V) | R22: Current (µA) | S22: Voltage (V) | T22: Current (µA) | W22: Sample 1 | X22: Sample 2 | Y22: Sample 3 | Z22: Sample 4 | AA22: Sample 5 | AB22: Sample 6 | AC22: Sample 7 | AD22: Sample 8 | AE22: Sample 9
B23: 45505 | C23: 7.6785371e-05 | D23: 0.1373291 | E23: 7.6785371e-05 | F23: 3.0510426 | G23: 7.6785371e-05 | H23: 4.075532 | I23: 7.6785371e-05 | J23: 5.4543376 | K23: 7.6785371e-05 | L23: 6.6234827 | M23: 7.6785371e-05 | N23: 8.0682087 | O23: 7.6785371e-05 | P23: 7.9198909 | Q23: 7.6785371e-05 | R23: 10.345159 | S23: 7.6785371e-05 | T23: 15.165949 | W23: =AVERAGE(J23,L23,N23,P23,R23,T23) -> 8.9295046
B24: 45505 | C24: 0.010058884 | D24: 0.59509277 | E24: 0.010058884 | F24: 3.4502172 | G24: 0.010058884 | H24: 4.6477461 | I24: 0.010058884 | J24: 6.1235976 | K24: 0.010058884 | L24: 7.4282455 | M24: 0.010058884 | N24: 9.1073465 | O24: 0.010058884 | P24: 9.2794681 | Q24: 0.010058884 | R24: 12.975512 | S24: 0.010058884 | T24: 20.695806 | W24: =AVERAGE(J24,L24,N24,P24,R24,T24) -> 10.934996
B25: 45505 | C25: 0.020041382 | D25: 0.96130371 | E25: 0.020041382 | F25: 3.8493943 | G25: 0.020041382 | H25: 5.2153802 | I25: 0.020041382 | J25: 6.8322277 | K25: 0.020041382 | L25: 8.2815289 | M25: 0.020041382 | N25: 10.238042 | O25: 0.020041382 | P25: 10.439458 | Q25: 0.020041382 | R25: 15.466695 | S25: 0.020041382 | T25: 26.35386 | W25: =AVERAGE(J25,L25,N25,P25,R25,T25) -> 12.935302
B26: 45505 | C26: 0.03002348 | D26: 1.4190674 | E26: 0.03002348 | F26: 4.2549777 | G26: 0.03002348 | H26: 5.8342862 | I26: 0.03002348 | J26: 7.5683212 | K26: 0.03002348 | L26: 9.1604495 | M26: 0.03002348 | N26: 11.413598 | O26: 0.03002348 | P26: 11.932707 | Q26: 0.03002348 | R26: 18.453193 | S26: 0.03002348 | T26: 31.352711 | W26: =AVERAGE(J26,L26,N26,P26,R26,T26) -> 14.980163
B27: 45505 | C27: 0.040005978 | D27: 1.8768311 | E27: 0.040005978 | F27: 4.6752119 | G27: 0.040005978 | H27: 6.4367127 | I27: 0.040005978 | J27: 8.3071637 | K27: 0.040005978 | L27: 10.084229 | M27: 0.040005978 | N27: 12.707257 | O27: 0.040005978 | P27: 13.588004 | Q27: 0.040005978 | R27: 22.045779 | S27: 0.040005978 | T27: 37.34951 | W27: =AVERAGE(J27,L27,N27,P27,R27,T27) -> 17.346991
B28: 45505 | C28: 0.049988076 | D28: 2.3025751 | E28: 0.049988076 | F28: 5.1018548 | G28: 0.049988076 | H28: 7.0583653 | I28: 0.049988076 | J28: 9.1091776 | K28: 0.049988076 | L28: 11.099567 | M28: 0.049988076 | N28: 13.985353 | O28: 0.049988076 | P28: 15.334859 | Q28: 0.049988076 | R28: 24.006867 | S28: 0.049988076 | T28: 44.399166 | W28: =AVERAGE(J28,L28,N28,P28,R28,T28) -> 19.655832
B29: 45505 | C29: 0.059970174 | D29: 2.806139 | E29: 0.059970174 | F29: 5.5358195 | G29: 0.059970174 | H29: 7.7029061 | I29: 0.059970174 | J29: 9.9331665 | K29: 0.059970174 | L29: 12.071872 | M29: 0.059970174 | N29: 15.117874 | O29: 0.059970174 | P29: 16.748457 | Q29: 0.059970174 | R29: 26.80934 | S29: 0.059970174 | T29: 50.69809 | W29: =AVERAGE(J29,L29,N29,P29,R29,T29) -> 21.896466
B30: 45505 | C30: 0.069952674 | D30: 3.2822132 | E30: 0.069952674 | F30: 5.9972525 | G30: 0.069952674 | H30: 8.3437848 | I30: 0.069952674 | J30: 10.710459 | K30: 0.069952674 | L30: 13.018541 | M30: 0.069952674 | N30: 16.424356 | O30: 0.069952674 | P30: 18.368049 | Q30: 0.069952674 | R30: 29.014878 | S30: 0.069952674 | T30: 56.420231 | W30: =AVERAGE(J30,L30,N30,P30,R30,T30) -> 23.992752
B31: 45505 | C31: 0.079934768 | D31: 3.7216663 | E31: 0.079934768 | F31: 6.56672 | G31: 0.079934768 | H31: 9.0469217 | I31: 0.079934768 | J31: 11.626916 | K31: 0.079934768 | L31: 14.064088 | M31: 0.079934768 | N31: 17.744565 | O31: 0.079934768 | P31: 20.225682 | Q31: 0.079934768 | R31: 33.595777 | S31: 0.079934768 | T31: 65.557337 | W31: =AVERAGE(J31,L31,N31,P31,R31,T31) -> 27.135727
B32: 45505 | C32: 0.08991687 | D32: 4.1428328 | E32: 0.08991687 | F32: 7.2909141 | G32: 0.08991687 | H32: 9.9798584 | I32: 0.08991687 | J32: 12.749372 | K32: 0.08991687 | L32: 15.350423 | M32: 0.08991687 | N32: 19.231405 | O32: 0.08991687 | P32: 22.502632 | Q32: 0.08991687 | R32: 38.860154 | S32: 0.08991687 | T32: 72.506285 | W32: =AVERAGE(J32,L32,N32,P32,R32,T32) -> 30.200045
B33: 45505 | C33: 0.099899366 | D33: 4.5497823 | E33: 0.099899366 | F33: 7.9958797 | G33: 0.099899366 | H33: 10.904555 | I33: 0.099899366 | J33: 13.859005 | K33: 0.099899366 | L33: 16.596475 | M33: 0.099899366 | N33: 20.761271 | O33: 0.099899366 | P33: 24.74113 | Q33: 0.099899366 | R33: 44.04211 | S33: 0.099899366 | T33: 81.423664 | W33: =AVERAGE(J33,L33,N33,P33,R33,T33) -> 33.570609
B34: 45505 | C34: 0.10988147 | D34: 4.9608612 | E34: 0.10988147 | F34: 8.6568999 | G34: 0.10988147 | H34: 11.71206 | I34: 0.10988147 | J34: 14.82307 | K34: 0.10988147 | L34: 17.637444 | M34: 0.10988147 | N34: 22.242618 | O34: 0.10988147 | P34: 26.4358 | Q34: 0.10988147 | R34: 49.095893 | S34: 0.10988147 | T34: 90.817118 | W34: =AVERAGE(J34,L34,N34,P34,R34,T34) -> 36.84199
... B303: 45505 | C303: 7.6785371e-05 | D303: 3.0510426 | E303: 7.6785371e-05 | F303: 4.075532 | G303: 7.6785371e-05 | H303: 5.4543376 | I303: 7.6785371e-05 | J303: 6.6234827 | K303: 7.6785371e-05 | L303: 8.0682087 | M303: 7.6785371e-05 | N303: 7.9198909 | O303: 7.6785371e-05 | P303: 10.345159 | Q303: 7.6785371e-05 | R303: 15.165949 | S303: 7.6785371e-05 | T303: 13.627839 | W303: =AVERAGE(J303,L303,N303,P303,R303,T303) -> 10.291755
W304: =AVERAGE(J304,L304,N304,P304,R304,T304) -> #DIV/0!
W305: =AVERAGE(J305,L305,N305,P305,R305,T305) -> #DIV/0!
W306: =AVERAGE(J306,L306,N306,P306,R306,T306) -> #DIV/0!
W307: =AVERAGE(J307,L307,N307,P307,R307,T307) -> #DIV/0!
W308: =AVERAGE(J308,L308,N308,P308,R308,T308) -> #DIV/0!
W309: =AVERAGE(J309,L309,N309,P309,R309,T309) -> #DIV/0!
W310: =AVERAGE(J310,L310,N310,P310,R310,T310) -> #DIV/0!
W311: =AVERAGE(J311,L311,N311,P311,R311,T311) -> #DIV/0!
W312: =AVERAGE(J312,L312,N312,P312,R312,T312) -> #DIV/0!
W313: =AVERAGE(J313,L313,N313,P313,R313,T313) -> #DIV/0!
W314: =AVERAGE(J314,L314,N314,P314,R314,T314) -> #DIV/0!
W315: =AVERAGE(J315,L315,N315,P315,R315,T315) -> #DIV/0!
... W423: =AVERAGE(J423,L423,N423,P423,R423,T423) -> #DIV/0!
V425: Summary of results
V427: Add in here average values, tables, figures or any result you've got

Sheet Biosensor2_Lacasa
D3: Lab-Book
H5: Supervisor: | I5: Johann F. Osma
B8: Experiment Nº: | C8: 6 | H8: Researcher: | I8: =Description!I8 -> Ailin Prado Falla
B9: Title: | C9: CV measurement of Laccase assembling in Biosensor 2.
B11: Description of the experiment
B13: CV measurement of Laccase assembling in Biosensor 2 using remotly controlled syringe pumps.
B20: Measurement: | V20: Calculation and/or formula:
B21: Date | C21: Description | E21: Description | G21: Description | I21: Description | K21: Description | M21: Description | O21: Description | Q21: Description | S21: Description | V21: Date | W21: Description
C22: Voltage (V) | D22: Current (µA) | E22: Voltage (V) | F22: Current (µA) | G22: Voltage (V) | H22: Current (µA) | I22: Voltage (V) | J22: Current (µA) | K22: Voltage (V) | L22: Current (µA) | M22: Voltage (V) | N22: Current (µA) | O22: Voltage (V) | P22: Current (µA) | Q22: Voltage (V) | R22: Current (µA) | S22: Voltage (V) | T22: Current (µA) | W22: Sample 1 | X22: Sample 2 | Y22: Sample 3 | Z22: Sample 4 | AA22: Sample 5 | AB22: Sample 6 | AC22: Sample 7 | AD22: Sample 8 | AE22: Sample 9
B23: 45505 | C23: 7.6785371e-05 | D23: 0.22888184 | E23: 7.6785371e-05 | F23: 4.3630123 | G23: 7.6785371e-05 | H23: 4.6495771 | I23: 7.6785371e-05 | J23: 5.1732659 | K23: 7.6785371e-05 | L23: 3.7491322 | M23: 7.6785371e-05 | N23: -2.2201777 | O23: 7.6785371e-05 | P23: -2.6504993 | Q23: 7.6785371e-05 | R23: -3.9688826 | S23: 7.6785371e-05 | T23: -4.6921492 | W23: =AVERAGE(J23,L23,N23,P23,R23,T23) -> -0.76821844
B24: 45505 | C24: 0.010058884 | D24: 0.4119873 | E24: 0.010058884 | F24: 4.8967719 | G24: 0.010058884 | H24: 5.5394816 | I24: 0.010058884 | J24: 6.6637683 | K24: 0.010058884 | L24: 11.924934 | M24: 0.010058884 | N24: 9.7276211 | O24: 0.010058884 | P24: 12.089729 | Q24: 0.010058884 | R24: 12.492561 | S24: 0.010058884 | T24: 12.309456 | W24: =AVERAGE(J24,L24,N24,P24,R24,T24) -> 10.868012
B25: 45505 | C25: 0.020041382 | D25: 0.59509277 | E25: 0.020041382 | F25: 5.3215837 | G25: 0.020041382 | H25: 6.2426186 | I25: 0.020041382 | J25: 8.2275128 | K25: 0.020041382 | L25: 20.036626 | M25: 0.020041382 | N25: 21.538115 | O25: 0.020041382 | P25: 27.077127 | Q25: 0.020041382 | R25: 28.926539 | S25: 0.020041382 | T25: 29.649806 | W25: =AVERAGE(J25,L25,N25,P25,R25,T25) -> 22.575954
B26: 45505 | C26: 0.03002348 | D26: 0.77819824 | E26: 0.03002348 | F26: 6.0018301 | G26: 0.03002348 | H26: 6.9860387 | I26: 0.03002348 | J26: 9.8571754 | K26: 0.03002348 | L26: 28.212404 | M26: 0.03002348 | N26: 33.604956 | O26: 0.03002348 | P26: 42.165256 | Q26: 0.03002348 | R26: 45.8915 | S26: 0.03002348 | T26: 46.861982 | W26: =AVERAGE(J26,L26,N26,P26,R26,T26) -> 34.432212
B27: 45505 | C27: 0.040005978 | D27: 1.0528564 | E27: 0.040005978 | F27: 6.7013049 | G27: 0.040005978 | H27: 7.8008699 | I27: 0.040005978 | J27: 11.711144 | K27: 0.040005978 | L27: 36.461425 | M27: 0.040005978 | N27: 46.2852 | O27: 0.040005978 | P27: 57.802701 | Q27: 0.040005978 | R27: 63.790345 | S27: 0.040005978 | T27: 65.264368 | W27: =AVERAGE(J27,L27,N27,P27,R27,T27) -> 46.885864
B28: 45505 | C28: 0.049988076 | D28: 1.2405634 | E28: 0.049988076 | F28: 7.4785995 | G28: 0.049988076 | H28: 8.7676811 | I28: 0.049988076 | J28: 13.523002 | K28: 0.049988076 | L28: 45.131612 | M28: 0.049988076 | N28: 59.642935 | O28: 0.049988076 | P28: 74.749374 | Q28: 0.049988076 | R28: 83.602667 | S28: 0.049988076 | T28: 85.278106 | W28: =AVERAGE(J28,L28,N28,P28,R28,T28) -> 60.321283
B29: 45505 | C29: 0.059970174 | D29: 1.5152216 | E29: 0.059970174 | F29: 8.3245587 | G29: 0.059970174 | H29: 9.8196387 | I29: 0.059970174 | J29: 15.574732 | K29: 0.059970174 | L29: 54.991984 | M29: 0.059970174 | N29: 74.081016 | O29: 0.059970174 | P29: 93.032742 | Q29: 0.059970174 | R29: 105.33762 | S29: 0.059970174 | T29: 107.31516 | W29: =AVERAGE(J29,L29,N29,P29,R29,T29) -> 75.055542
B30: 45505 | C30: 0.069952674 | D30: 1.8081903 | E30: 0.069952674 | F30: 9.1522098 | G30: 0.069952674 | H30: 11.027236 | I30: 0.069952674 | J30: 17.907529 | K30: 0.069952674 | L30: 65.14535 | M30: 0.069952674 | N30: 89.370561 | O30: 0.069952674 | P30: 112.56123 | Q30: 0.069952674 | R30: 127.83246 | S30: 0.069952674 | T30: 131.23827 | W30: =AVERAGE(J30,L30,N30,P30,R30,T30) -> 90.675899
B31: 45505 | C31: 0.079934768 | D31: 2.1469355 | E31: 0.079934768 | F31: 9.9285889 | G31: 0.079934768 | H31: 12.19913 | I31: 0.079934768 | J31: 20.131378 | K31: 0.079934768 | L31: 75.362778 | M31: 0.079934768 | N31: 105.05381 | O31: 0.079934768 | P31: 132.73058 | Q31: 0.079934768 | R31: 150.72098 | S31: 0.079934768 | T31: 155.78394 | W31: =AVERAGE(J31,L31,N31,P31,R31,T31) -> 106.63058
B32: 45505 | C32: 0.08991687 | D32: 2.5223255 | E32: 0.08991687 | F32: 10.708628 | G32: 0.08991687 | H32: 13.318839 | I32: 0.08991687 | J32: 22.143741 | K32: 0.08991687 | L32: 85.186553 | M32: 0.08991687 | N32: 120.02287 | O32: 0.08991687 | P32: 152.2408 | Q32: 0.08991687 | R32: 173.8842 | S32: 0.08991687 | T32: 180.15566 | W32: =AVERAGE(J32,L32,N32,P32,R32,T32) -> 122.2723
B33: 45505 | C33: 0.099899366 | D33: 2.9192042 | E33: 0.099899366 | F33: 11.604943 | G33: 0.099899366 | H33: 14.551158 | I33: 0.099899366 | J33: 24.380407 | K33: 0.099899366 | L33: 95.577931 | M33: 0.099899366 | N33: 135.47721 | O33: 0.099899366 | P33: 171.75097 | Q33: 0.099899366 | R33: 196.69948 | S33: 0.099899366 | T33: 204.37169 | W33: =AVERAGE(J33,L33,N33,P33,R33,T33) -> 138.04295
B34: 45505 | C34: 0.10988147 | D34: 3.3394361 | E34: 0.10988147 | F34: 12.617531 | G34: 0.10988147 | H34: 15.911651 | I34: 0.10988147 | J34: 26.949415 | K34: 0.10988147 | L34: 107.49826 | M34: 0.10988147 | N34: 151.0231 | O34: 0.10988147 | P34: 192.51547 | Q34: 0.10988147 | R34: 220.01829 | S34: 0.10988147 | T34: 228.44129 | W34: =AVERAGE(J34,L34,N34,P34,R34,T34) -> 154.40764
... B303: 45505 | C303: 7.6785371e-05 | D303: 4.3630123 | E303: 7.6785371e-05 | F303: 4.6495771 | G303: 7.6785371e-05 | H303: 5.1732659 | I303: 7.6785371e-05 | J303: 3.7491322 | K303: 7.6785371e-05 | L303: -2.2201777 | M303: 7.6785371e-05 | N303: -2.6504993 | O303: 7.6785371e-05 | P303: -3.9688826 | Q303: 7.6785371e-05 | R303: -4.6921492 | S303: 7.6785371e-05 | T303: -4.0740967 | W303: =AVERAGE(J303,L303,N303,P303,R303,T303) -> -2.3094455
W304: =AVERAGE(J304,L304,N304,P304,R304,T304) -> #DIV/0!
W305: =AVERAGE(J305,L305,N305,P305,R305,T305) -> #DIV/0!
W306: =AVERAGE(J306,L306,N306,P306,R306,T306) -> #DIV/0!
W307: =AVERAGE(J307,L307,N307,P307,R307,T307) -> #DIV/0!
W308: =AVERAGE(J308,L308,N308,P308,R308,T308) -> #DIV/0!
W309: =AVERAGE(J309,L309,N309,P309,R309,T309) -> #DIV/0!
W310: =AVERAGE(J310,L310,N310,P310,R310,T310) -> #DIV/0!
W311: =AVERAGE(J311,L311,N311,P311,R311,T311) -> #DIV/0!
W312: =AVERAGE(J312,L312,N312,P312,R312,T312) -> #DIV/0!
W313: =AVERAGE(J313,L313,N313,P313,R313,T313) -> #DIV/0!
W314: =AVERAGE(J314,L314,N314,P314,R314,T314) -> #DIV/0!
W315: =AVERAGE(J315,L315,N315,P315,R315,T315) -> #DIV/0!
... W423: =AVERAGE(J423,L423,N423,P423,R423,T423) -> #DIV/0!
V425: Summary of results
V427: Add in here average values, tables, figures or any result you've got

Sheet Biosensor3_Aptes
D3: Lab-Book
H5: Supervisor: | I5: Johann F. Osma
B8: Experiment Nº: | C8: 7 | H8: Researcher: | I8: =Description!I8 -> Ailin Prado Falla
B9: Title: | C9: CV measurement of Aptes assembling in Biosensor 3.
B11: Description of the experiment
B13: CV measurement of Aptes assembling in Biosensor 3 using remotly controlled syringe pumps.
B20: Measurement: | V20: Calculation and/or formula:
B21: Date | C21: Description | E21: Description | G21: Description | I21: Description | K21: Description | M21: Description | O21: Description | Q21: Description | S21: Description | V21: Date | W21: BioS3 | X21: BioS3 | Y21: BioS3
C22: Voltage (V) | D22: Current (µA) | E22: Voltage (V) | F22: Current (µA) | G22: Voltage (V) | H22: Current (µA) | I22: Voltage (V) | J22: Current (µA) | K22: Voltage (V) | L22: Current (µA) | M22: Voltage (V) | N22: Current (µA) | O22: Voltage (V) | P22: Current (µA) | Q22: Voltage (V) | R22: Current (µA) | S22: Voltage (V) | T22: Current (µA) | W22: Bio-APTES | X22: Bio-Glut | Y22: Bio-Lac | Z22: Sample 4 | AA22: Sample 5 | AB22: Sample 6 | AC22: Sample 7 | AD22: Sample 8 | AE22: Sample 9
B23: 45505 | C23: 7.6785371e-05 | D23: 0.045776367 | E23: 7.6785371e-05 | F23: -0.13481355 | G23: 7.6785371e-05 | H23: -0.26536965 | I23: 7.6785371e-05 | J23: -0.41771579 | K23: 7.6785371e-05 | L23: -0.65630579 | M23: 7.6785371e-05 | N23: -0.58837271 | O23: 7.6785371e-05 | P23: -0.70908785 | Q23: 7.6785371e-05 | R23: -1.0011435 | S23: 7.6785371e-05 | T23: -0.83909273 | W23: =AVERAGE(J23,L23,N23,P23,R23,T23) -> -0.70195305 | X23: =Biosensor3_Glut!W23 -> 0.26688031 | Y23: =Biosensor3_Lacasa!W23 -> -0.17708099
B24: 45505 | C24: 0.010058884 | D24: 0.1373291 | E24: 0.010058884 | F24: -0.033279896 | G24: 0.010058884 | H24: -0.10661483 | I24: 0.010058884 | J24: -0.21629667 | K24: 0.010058884 | L24: -0.43859005 | M24: 0.010058884 | N24: -0.38741136 | O24: 0.010058884 | P24: -0.47287703 | Q24: 0.010058884 | R24: -0.70817232 | S24: 0.010058884 | T24: -0.576334 | W24: =AVERAGE(J24,L24,N24,P24,R24,T24) -> -0.46661357 | X24: =Biosensor3_Glut!W24 -> 0.43439384 | Y24: =Biosensor3_Lacasa!W24 -> -0.083238006
B25: 45505 | C25: 0.020041382 | D25: 0.1373291 | E25: 0.020041382 | F25: 0.05323863 | G25: 0.020041382 | H25: 0.045548201 | I25: 0.020041382 | J25: -0.021744013 | K25: 0.020041382 | L25: -0.23387504 | M25: 0.020041382 | N25: -0.19615483 | O25: 0.020041382 | P25: -0.24948597 | Q25: 0.020041382 | R25: -0.42343855 | S25: 0.020041382 | T25: -0.32272816 | W25: =AVERAGE(J25,L25,N25,P25,R25,T25) -> -0.24123776 | X25: =Biosensor3_Glut!W25 -> 0.59435415 | Y25: =Biosensor3_Lacasa!W25 -> 0.013656815
B26: 45505 | C26: 0.03002348 | D26: 0.22888184 | E26: 0.03002348 | F26: 0.13563752 | G26: 0.03002348 | H26: 0.20064092 | I26: 0.03002348 | J26: 0.17015338 | K26: 0.03002348 | L26: -0.042069197 | M26: 0.03002348 | N26: -0.013870478 | O26: 0.03002348 | P26: -0.035247803 | Q26: 0.03002348 | R26: -0.14877558 | S26: 0.03002348 | T26: -0.075531006 | W26: =AVERAGE(J26,L26,N26,P26,R26,T26) -> -0.024223447 | X26: =Biosensor3_Glut!W26 -> 0.76545354 | Y26: =Biosensor3_Lacasa!W26 -> 0.11213855
B27: 45505 | C27: 0.040005978 | D27: 0.32043457 | E27: 0.040005978 | F27: 0.21364164 | G27: 0.040005978 | H27: 0.35875487 | I27: 0.040005978 | J27: 0.37276268 | K27: 0.040005978 | L27: 0.14268708 | M27: 0.040005978 | N27: 0.160357 | O27: 0.040005978 | P27: 0.16621661 | Q27: 0.040005978 | R27: 0.12130976 | S27: 0.040005978 | T27: 0.16708612 | W27: =AVERAGE(J27,L27,N27,P27,R27,T27) -> 0.18840321 | X27: =Biosensor3_Glut!W27 -> 0.96157785 | Y27: =Biosensor3_Lacasa!W27 -> 0.21028455
B28: 45505 | C28: 0.049988076 | D28: 0.46234131 | E28: 0.049988076 | F28: 0.29109645 | G28: 0.049988076 | H28: 0.50743866 | I28: 0.049988076 | J28: 0.58013272 | K28: 0.049988076 | L28: 0.32076001 | M28: 0.049988076 | N28: 0.34016943 | O28: 0.049988076 | P28: 0.38338304 | Q28: 0.049988076 | R28: 0.39414167 | S28: 0.049988076 | T28: 0.40178537 | W28: =AVERAGE(J28,L28,N28,P28,R28,T28) -> 0.40339537 | X28: =Biosensor3_Glut!W28 -> 1.1806056 | Y28: =Biosensor3_Lacasa!W28 -> 0.30411235
B29: 45505 | C29: 0.059970174 | D29: 0.54473877 | E29: 0.059970174 | F29: 0.36571288 | G29: 0.059970174 | H29: 0.64394593 | I29: 0.059970174 | J29: 0.76791024 | K29: 0.059970174 | L29: 0.49443817 | M29: 0.059970174 | N29: 0.52739763 | O29: 0.059970174 | P29: 0.60659194 | Q29: 0.059970174 | R29: 0.64834046 | S29: 0.059970174 | T29: 0.65932703 | W29: =AVERAGE(J29,L29,N29,P29,R29,T29) -> 0.61733425 | X29: =Biosensor3_Glut!W29 -> 1.4021974 | Y29: =Biosensor3_Lacasa!W29 -> 0.39151601
B30: 45505 | C30: 0.069952674 | D30: 0.69122314 | E30: 0.069952674 | F30: 0.44051266 | G30: 0.069952674 | H30: 0.77981234 | I30: 0.069952674 | J30: 0.93920803 | K30: 0.069952674 | L30: 0.66243982 | M30: 0.069952674 | N30: 0.72130919 | O30: 0.069952674 | P30: 0.83813238 | Q30: 0.069952674 | R30: 0.9244678 | S30: 0.069952674 | T30: 0.9260242 | W30: =AVERAGE(J30,L30,N30,P30,R30,T30) -> 0.83526357 | X30: =Biosensor3_Glut!W30 -> 1.6026551 | Y30: =Biosensor3_Lacasa!W30 -> 0.47281607
B31: 45505 | C31: 0.079934768 | D31: 0.82857609 | E31: 0.079934768 | F31: 0.51760125 | G31: 0.079934768 | H31: 0.91119242 | I31: 0.079934768 | J31: 1.1033645 | K31: 0.079934768 | L31: 0.83419538 | M31: 0.079934768 | N31: 0.91906619 | O31: 0.079934768 | P31: 1.0762644 | Q31: 0.079934768 | R31: 1.1918974 | S31: 0.079934768 | T31: 1.1997709 | W31: =AVERAGE(J31,L31,N31,P31,R31,T31) -> 1.0540931 | X31: =Biosensor3_Glut!W31 -> 1.7781796 | Y31: =Biosensor3_Lacasa!W31 -> 0.54473186
B32: 45505 | C32: 0.08991687 | D32: 0.92012882 | E32: 0.08991687 | F32: 0.59752798 | G32: 0.08991687 | H32: 1.0435796 | I32: 0.08991687 | J32: 1.2662396 | K32: 0.08991687 | L32: 1.0124512 | M32: 0.08991687 | N32: 1.1153584 | O32: 0.08991687 | P32: 1.3152208 | Q32: 0.08991687 | R32: 1.4498053 | S32: 0.08991687 | T32: 1.4692149 | W32: =AVERAGE(J32,L32,N32,P32,R32,T32) -> 1.2713817 | X32: =Biosensor3_Glut!W32 -> 1.92813 | Y32: =Biosensor3_Lacasa!W32 -> 0.60923167
B33: 45505 | C33: 0.099899366 | D33: 0.90684414 | E33: 0.099899366 | F33: 0.67461658 | G33: 0.099899366 | H33: 1.1748686 | I33: 0.099899366 | J33: 1.4200501 | K33: 0.099899366 | L33: 1.1933622 | M33: 0.099899366 | N33: 1.3103685 | O33: 0.099899366 | P33: 1.5521631 | Q33: 0.099899366 | R33: 1.7008467 | S33: 0.099899366 | T33: 1.7363701 | W33: =AVERAGE(J33,L33,N33,P33,R33,T33) -> 1.4855268 | X33: =Biosensor3_Glut!W33 -> 2.0694133 | Y33: =Biosensor3_Lacasa!W33 -> 0.66871142
B34: 45505 | C34: 0.10988147 | D34: 0.98283291 | E34: 0.10988147 | F34: 0.73888755 | G34: 0.10988147 | H34: 1.3100023 | I34: 0.10988147 | J34: 1.5876861 | K34: 0.10988147 | L34: 1.3813229 | M34: 0.10988147 | N34: 1.5013504 | O34: 0.10988147 | P34: 1.7876401 | Q34: 0.10988147 | R34: 1.9387045 | S34: 0.10988147 | T34: 1.9981232 | W34: =AVERAGE(J34,L34,N34,P34,R34,T34) -> 1.6991378 | X34: =Biosensor3_Glut!W34 -> 2.2186007 | Y34: =Biosensor3_Lacasa!W34 -> 0.7241627
... B177: 45505 | C177: 7.6785371e-05 | D177: -0.13481355 | E177: 7.6785371e-05 | F177: -0.26536965 | G177: 7.6785371e-05 | H177: -0.41771579 | I177: 7.6785371e-05 | J177: -0.65630579 | K177: 7.6785371e-05 | L177: -0.58837271 | M177: 7.6785371e-05 | N177: -0.70908785 | O177: 7.6785371e-05 | P177: -1.0011435 | Q177: 7.6785371e-05 | R177: -0.83909273 | S177: 7.6785371e-05 | T177: -0.94621181 | W177: =AVERAGE(J177,L177,N177,P177,R177,T177) -> -0.79003572 | X177: =Biosensor3_Glut!W177 -> -2.3871441 | Y177: =Biosensor3_Lacasa!W177 -> -1.2079805
B178: 45505 | X178: =Biosensor3_Glut!W178 -> -2.477798 | Y178: =Biosensor3_Lacasa!W178 -> -1.2743267
B179: 45505 | X179: =Biosensor3_Glut!W179 -> -2.5537499 | Y179: =Biosensor3_Lacasa!W179 -> -1.3394674
B180: 45505 | X180: =Biosensor3_Glut!W180 -> -2.6252842 | Y180: =Biosensor3_Lacasa!W180 -> -1.405951
B181: 45505 | X181: =Biosensor3_Glut!W181 -> -2.707263 | Y181: =Biosensor3_Lacasa!W181 -> -1.4704967
B182: 45505 | X182: =Biosensor3_Glut!W182 -> -2.8309988 | Y182: =Biosensor3_Lacasa!W182 -> -1.5324941
B183: 45505 | X183: =Biosensor3_Glut!W183 -> -2.8814683 | Y183: =Biosensor3_Lacasa!W183 -> -1.5911803
B184: 45505 | X184: =Biosensor3_Glut!W184 -> -2.9749142 | Y184: =Biosensor3_Lacasa!W184 -> -1.6470131
B185: 45505 | X185: =Biosensor3_Glut!W185 -> -3.0913407 | Y185: =Biosensor3_Lacasa!W185 -> -1.7015335
B186: 45505 | X186: =Biosensor3_Glut!W186 -> -3.2047151 | Y186: =Biosensor3_Lacasa!W186 -> -1.753048
B187: 45505 | X187: =Biosensor3_Glut!W187 -> -3.3090026 | Y187: =Biosensor3_Lacasa!W187 -> -1.8006256
B188: 45505 | X188: =Biosensor3_Glut!W188 -> -3.4205157 | Y188: =Biosensor3_Lacasa!W188 -> -1.8437628
B189: 45505 | X189: =Biosensor3_Glut!W189 -> -3.528802 | Y189: =Biosensor3_Lacasa!W189 -> -1.8843519
... B303: 45505 | X303: =Biosensor3_Glut!W303 -> 0.29146258 | Y303: =Biosensor3_Lacasa!W303 -> -0.1416953
V305: Summary of results
V307: Add in here average values, tables, figures or any result you've got

Sheet Biosensor3_Glut
D3: Lab-Book
H5: Supervisor: | I5: Johann F. Osma
B8: Experiment Nº: | C8: 8 | H8: Researcher: | I8: =Description!I8 -> Ailin Prado Falla
B9: Title: | C9: CV measurement of Glutaraldehyde assembling in Biosensor 3.
B11: Description of the experiment
B13: CV measurement of Glutaraldehyde assembling in Biosensor 3 using remotly controlled syringe pumps.
B20: Measurement: | V20: Calculation and/or formula:
B21: Date | C21: Description | E21: Description | G21: Description | I21: Description | K21: Description | M21: Description | O21: Description | Q21: Description | S21: Description | V21: Date | W21: Description
C22: Voltage (V) | D22: Current (µA) | E22: Voltage (V) | F22: Current (µA) | G22: Voltage (V) | H22: Current (µA) | I22: Voltage (V) | J22: Current (µA) | K22: Voltage (V) | L22: Current (µA) | M22: Voltage (V) | N22: Current (µA) | O22: Voltage (V) | P22: Current (µA) | Q22: Voltage (V) | R22: Current (µA) | S22: Voltage (V) | T22: Current (µA) | W22: Sample 1 | X22: Sample 2 | Y22: Sample 3 | Z22: Sample 4 | AA22: Sample 5 | AB22: Sample 6 | AC22: Sample 7 | AD22: Sample 8 | AE22: Sample 9
