Workbook

Sheet Description
D3: Lab-Book
H5: Supervisor: | I5: Johann F. Osma
B8: Experiment Nº: | C8: 40 | H8: Researcher: | I8: Ailin Prado Falla
B9: Title: | C9: Acetaminophen (APAP) Electrochemical Impedance Spectroscopy (EIS) measurements for Lacase Biosensors with comertial potentiostat | H9: Starting Date: | I9: 45206
B11: Observations
B12: The objective of this experiment is to characterize the newly developed lacase biosensor designed for a microfluidic system potentiostat with different concentrations of APAP. This was made remotly using four syringe pumps controled with an arduino uno. The measurements were made in a commertial potentiostat for EIS for 4 sensors and 4 biosensors.
B20: Follow up of the experimentation
B21: Date | C21: Description | G21: Stage | I21: Location
B23: 45506 | C23: Sensor 1 EIS 0% Acetaminophen
B24: 45505 | C24: Sensor 1 EIS 15% Acetaminophen
B25: 45503 | C25: Sensor 1 EIS 30% Acetaminophen
B26: 45503 | C26: Sensor 1 EIS 45% Acetaminophen
B27: 45504 | C27: Sensor 1 EIS 60% Acetaminophen
B28: 45506 | C28: Sensor 2 EIS 0% Acetaminophen
B29: 45505 | C29: Sensor 2 EIS 15% Acetaminophen
B30: 45503 | C30: Sensor 2 EIS 30% Acetaminophen
B31: 45503 | C31: Sensor 2 EIS 45% Acetaminophen
B32: 45504 | C32: Sensor 2 EIS 60% Acetaminophen
B33: 45506 | C33: Sensor 3 EIS 0% Acetaminophen
B34: 45505 | C34: Sensor 3 EIS 15% Acetaminophen
... B64: 45632 | C64: Biosensors Average
B68: Sample numbering/codification
B71: List of Reagents and/or materials
B72: Name of Reagent or material | E72: Provider | G72: Lot number | I72: Approx. Quantity | K72: Date
B74: Lab book | E74: Biomicrosystems | I74: 1
B75: Potenciostat | E75: Biomicrosystems | I75: 1
B76: Mili Q | E76: Biomicrosystems | I76: 1 ml
B77: APAP 15% | E77: Biomicrosystems | I77: 1 ml
B78: APAP 30% | E78: Biomicrosystems | I78: 1 ml
B79: APAP 45% | E79: Biomicrosystems | I79: 1 ml
B80: APAP 60% | E80: Biomicrosystems | I80: 1 ml

Sheet Sensor1_0%
D3: Lab-Book
H5: Supervisor: | I5: Johann F. Osma
B8: Experiment Nº: | C8: =1 -> 1 | H8: Researcher: | I8: =Description!I8 -> Ailin Prado Falla
B9: Title: | C9: EIS for sensor 1 with APAP 0% | H9: Starting Date: | I9: 45506
B11: Description of the experiment
B13: EIS for APAP 0% in sensor 1 using remotly controlled syringe pumps and commercial potentiostat.
B20: Measurement: | N20: Calculation and/or formula:
B21: Date | N21: Date | O21: Description
C22: freq / Hz | D22: neg. Phase / ° | E22: Idc / uA | F22: Z / Ohm | G22: Z' / Ohm | H22: -Z'' / Ohm | I22: Cs / F | O22: Sample 1 | P22: Sample 2 | Q22: Sample 3 | R22: Sample 4 | S22: Sample 5 | T22: Sample 6 | U22: Sample 7 | V22: Sample 8 | W22: Sample 9
B23: 45506 | C23: 50000 | D23: 88.587464 | E23: 11.444092 | F23: 2524.4661 | G23: 62.23036 | H23: 2523.699 | I23: 1.2612831e-09
B24: 45506 | C24: 35714.285 | D24: -16.764249 | E24: 11.444092 | F24: 1580.4575 | G24: 1513.2875 | H24: -455.85832 | I24: -9.7757094e-09
B25: 45506 | C25: 25641.025 | D25: -44.668353 | E25: 11.444092 | F25: 1465.2437 | G25: 1042.0636 | H25: -1030.0692 | I25: -6.0258501e-09
B26: 45506 | C26: 18390.805 | D26: -52.807061 | E26: 11.764765 | F26: 1204.1006 | G26: 727.87993 | H26: -959.19184 | I26: -9.0222306e-09
B27: 45506 | C27: 13136.289 | D27: -34.72556 | E27: 12.222528 | F27: 691.41531 | G27: 568.26733 | H27: -393.86212 | I27: -3.0761196e-08
B28: 45506 | C28: 9302.3262 | D28: 25.975268 | E28: 12.863398 | F28: 521.90454 | G28: 469.18341 | H28: 228.58539 | I28: 7.4847984e-08
B29: 45506 | C29: 6644.5186 | D29: 62.569399 | E29: 13.229609 | F29: 908.64307 | G29: 418.58813 | H29: 806.48385 | I29: 2.9700307e-08
B30: 45506 | C30: 4761.9048 | D30: 73.602606 | E30: 13.687372 | F30: 1623.1781 | G30: 458.21965 | H30: 1557.1583 | I30: 2.1463802e-08
B31: 45506 | C31: 3401.3606 | D31: 75.578396 | E31: 14.003205 | F31: 2675.9629 | G31: 666.46219 | H31: 2591.6415 | I31: 1.8054794e-08
B32: 45506 | C32: 2433.8301 | D32: 70.589552 | E32: 1.4259553 | F32: 4060.4249 | G32: 1349.4137 | H32: 3829.6388 | I32: 1.7075446e-08
B33: 45506 | C33: 1732.7268 | D33: 61.904028 | E33: 1.4616609 | F33: 5591.4343 | G33: 2633.2852 | H33: 4932.5395 | I33: 1.8621706e-08
B34: 45506 | C34: 1238.3901 | D34: 52.209534 | E34: 1.4891291 | F34: 7051.795 | G34: 4321.1677 | H34: 5572.7303 | I34: 2.3061876e-08
... B62: 45506 | C62: 0.10000128 | D62: -5.933045 | E62: 5.7051968 | F62: 2845.7968 | G62: 2830.5529 | H62: -294.15922 | I62: -0.0054104338
N425: Summary of results
N427: Add in here average values, tables, figures or any result you've got

Sheet Sensor1_15%
D3: Lab-Book
H5: Supervisor: | I5: Johann F. Osma
B8: Experiment Nº: | C8: 2 | H8: Researcher: | I8: =Description!I8 -> Ailin Prado Falla
B9: Title: | C9: EIS for sensor 1 with APAP 15% | H9: Starting Date: | I9: 45505
B11: Description of the experiment
B13: EIS for APAP 15% in sensor 1 using remotly controlled syringe pumps and commercial potentiostat.
B20: Measurement: | L20: Calculation and/or formula:
B21: Date | L21: Date | M21: Description
C22: freq / Hz | D22: neg. Phase / ° | E22: Idc / uA | F22: Z / Ohm | G22: Z' / Ohm | H22: -Z'' / Ohm | I22: Cs / F | M22: Sample 1 | N22: Sample 2 | O22: Sample 3 | P22: Sample 4 | Q22: Sample 5 | R22: Sample 6 | S22: Sample 7 | T22: Sample 8 | U22: Sample 9
B23: 45505 | C23: 50000 | D23: 83.304002 | E23: 14.190674 | F23: 3123.8957 | G23: 364.2505 | H23: 3102.587 | I23: 1.0259499e-09
B24: 45505 | C24: 35714.285 | D24: -7.7696642 | E24: 15.106201 | F24: 1662.0909 | G24: 1646.8321 | H24: -224.69971 | I24: -1.9832417e-08
B25: 45505 | C25: 25641.025 | D25: -21.029445 | E25: 15.106201 | F25: 1597.764 | G25: 1491.3467 | H25: -573.3539 | I25: -1.0825849e-08
B26: 45505 | C26: 18390.805 | D26: 6.9749945 | E26: 15.60998 | F26: 2126.0194 | G26: 2110.2853 | H26: 258.17563 | I26: 3.3520012e-08
B27: 45505 | C27: 13136.289 | D27: 25.050621 | E27: 15.701532 | F27: 2930.803 | G27: 2655.1142 | H27: 1240.9571 | I27: 9.7631656e-09
B28: 45505 | C28: 9302.3262 | D28: 31.837752 | E28: 16.250849 | F28: 3856.7771 | G28: 3276.5068 | H28: 2034.5104 | I28: 8.4094706e-09
B29: 45505 | C29: 6644.5186 | D29: 33.665914 | E29: 16.159296 | F29: 4940.9853 | G29: 4112.3033 | H29: 2739.0321 | I29: 8.7449934e-09
B30: 45505 | C30: 4761.9048 | D30: 31.255648 | E30: 16.067743 | F30: 5868.6514 | G30: 5016.8796 | H30: 3044.994 | I30: 1.0976225e-08
B31: 45505 | C31: 3401.3606 | D31: 26.4204 | E31: 15.733576 | F31: 7064.2589 | G31: 6326.421 | H31: 3143.2708 | I31: 1.4886262e-08
B32: 45505 | C32: 2433.8301 | D32: 22.350738 | E32: 1.4927912 | F32: 7928.4532 | G32: 7332.8149 | H32: 3014.9952 | I32: 2.1689186e-08
B33: 45505 | C33: 1732.7268 | D33: 18.836466 | E33: 1.4287019 | F33: 8466.4072 | G33: 8012.98 | H33: 2733.533 | I33: 3.3602045e-08
B34: 45505 | C34: 1238.3901 | D34: 15.98291 | E34: 1.3939118 | F34: 8936.8336 | G34: 8591.3702 | H34: 2460.7626 | I34: 5.2226741e-08
... B62: 45505 | C62: 0.10000128 | D62: -6.1497819 | E62: 1.1009383 | F62: 13799.244 | G62: 13719.833 | H62: -1478.285 | I62: -0.001076605
L64: Summary of results
L66: Add in here average values, tables, figures or any result you've got

Sheet Sensor1_30%
D3: Lab-Book
H5: Supervisor: | I5: Johann F. Osma
B8: Experiment Nº: | C8: 3 | H8: Researcher: | I8: =Description!I8 -> Ailin Prado Falla
B9: Title: | C9: EIS for sensor 1 with APAP 15% | H9: Starting Date: | I9: 45503
B11: Description of the experiment
B13: EIS for APAP 30% in sensor 1 using remotly controlled syringe pumps and commercial potentiostat.
B20: Measurement: | L20: Calculation and/or formula:
B21: Date | L21: Date | M21: Description
C22: freq / Hz | D22: neg. Phase / ° | E22: Idc / uA | F22: Z / Ohm | G22: Z' / Ohm | H22: -Z'' / Ohm | I22: Cs / F | M22: Sample 1 | N22: Sample 2 | O22: Sample 3 | P22: Sample 4 | Q22: Sample 5 | R22: Sample 6 | S22: Sample 7 | T22: Sample 8 | U22: Sample 9
B23: 45503 | C23: 50000 | D23: -33.500006 | E23: 57.220459 | F23: 1494.6187 | G23: 1246.3413 | H23: -824.93548 | I23: -3.8586034e-09
B24: 45503 | C24: 35714.285 | D24: 4.5994613 | E24: 57.220459 | F24: 906.83048 | G24: 903.91015 | H24: 72.718331 | I24: 6.1282189e-08
B25: 45503 | C25: 25641.025 | D25: 3.8600043 | E25: 57.220459 | F25: 1166.2771 | G25: 1163.6315 | H25: 78.512417 | I25: 7.9058104e-08
B26: 45503 | C26: 18390.805 | D26: 9.3437754 | E26: 57.541847 | F26: 1633.5353 | G26: 1611.8615 | H26: 265.21712 | I26: 3.2630058e-08
B27: 45503 | C27: 13136.289 | D27: 11.042218 | E27: 57.541847 | F27: 1777.6067 | G27: 1744.6966 | H27: 340.46901 | I27: 3.5585236e-08
B28: 45503 | C28: 9302.3262 | D28: 12.00116 | E28: 59.189796 | F28: 1931.8054 | G28: 1889.5827 | H28: 401.6832 | I28: 4.2593655e-08
B29: 45503 | C29: 6644.5186 | D29: 11.981402 | E29: 58.732033 | F29: 2099.6051 | G29: 2053.8653 | H29: 435.8658 | I29: 5.4954571e-08
B30: 45503 | C30: 4761.9048 | D30: 10.761758 | E30: 58.548927 | F30: 2216.9888 | G30: 2177.9966 | H30: 413.96865 | I30: 8.0736882e-08
B31: 45503 | C31: 3401.3606 | D31: 9.0445498 | E31: 58.242153 | F31: 2340.6677 | G31: 2311.5648 | H31: 367.95854 | I31: 1.2716528e-07
B32: 45503 | C32: 2433.8301 | D32: 7.1959129 | E32: 58.049892 | F32: 2425.64 | G32: 2406.5348 | H32: 303.84164 | I32: 2.1521998e-07
B33: 45503 | C33: 1732.7268 | D33: 6.0735227 | E33: 57.793545 | F33: 2464.9605 | G33: 2451.1245 | H33: 260.80406 | I33: 3.5218892e-07
B34: 45503 | C34: 1238.3901 | D34: 5.1473917 | E34: 57.692837 | F34: 2508.7582 | G34: 2498.6409 | H34: 225.0811 | I34: 5.7098357e-07
... B62: 45503 | C62: 0.10000128 | D62: -4.5452717 | E62: 54.158855 | F62: 2776.89 | G62: 2768.1567 | H62: -220.05958 | I62: -0.0072322643
L64: Summary of results
L66: Add in here average values, tables, figures or any result you've got

Sheet Sensor1_45%
D3: Lab-Book
H5: Supervisor: | I5: Johann F. Osma
B8: Experiment Nº: | C8: 4 | H8: Researcher: | I8: =Description!I8 -> Ailin Prado Falla
B9: Title: | C9: EIS for sensor 1 with APAP 15% | H9: Starting Date: | I9: 45503
B11: Description of the experiment
B13: EIS for APAP 45% in sensor 1 using remotly controlled syringe pumps and commercial potentiostat.
B20: Measurement: | X20: Calculation and/or formula:
B21: Date | K21: Date | L21: Description
C22: freq / Hz | D22: neg. Phase / ° | E22: Idc / uA | F22: Z / Ohm | G22: Z' / Ohm | H22: -Z'' / Ohm | I22: Cs / F | L22: Sample 1 | M22: Sample 2 | N22: Sample 3 | O22: Sample 4 | P22: Sample 5 | Q22: Sample 6 | R22: Sample 7 | S22: Sample 8 | T22: Sample 9
B23: 45503 | C23: 50000 | D23: -57.198541 | E23: 81.942078 | F23: 1762.5869 | G23: 954.84551 | H23: -1481.5474 | I23: -2.1484962e-09
B24: 45503 | C24: 35714.285 | D24: -9.4635388 | E24: 81.942078 | F24: 979.28305 | G24: 965.95543 | H24: -161.01365 | I24: -2.7676774e-08
B25: 45503 | C25: 25641.025 | D25: -12.705821 | E25: 80.111023 | F25: 1072.0431 | G25: 1045.7912 | H25: -235.79087 | I25: -2.6324357e-08
B26: 45503 | C26: 18390.805 | D26: -7.0537424 | E26: 78.782318 | F26: 1391.2671 | G26: 1380.7372 | H26: -170.84799 | I26: -5.0653508e-08
B27: 45503 | C27: 13136.289 | D27: -2.405857 | E27: 77.958344 | F27: 1432.6235 | G27: 1431.3608 | H27: -60.138368 | I27: -2.0146323e-07
B28: 45503 | C28: 9302.3262 | D28: 1.3175544 | E28: 78.965424 | F28: 1501.0837 | G28: 1500.6869 | H28: 34.515372 | I28: 4.9569668e-07
B29: 45503 | C29: 6644.5186 | D29: 3.435771 | E29: 77.866791 | F29: 1580.9147 | G29: 1578.0732 | H29: 94.743562 | I29: 2.5281737e-07
B30: 45503 | C30: 4761.9048 | D30: 4.5559914 | E30: 76.676605 | F30: 1637.9487 | G30: 1632.7731 | H30: 130.10764 | I30: 2.5688375e-07
B31: 45503 | C31: 3401.3606 | D31: 4.9922819 | E31: 75.481796 | F31: 1713.8117 | G31: 1707.3103 | H31: 149.13855 | I31: 3.1374552e-07
B32: 45503 | C32: 2433.8301 | D32: 4.9878152 | E32: 74.694443 | F32: 1778.2239 | G32: 1771.4901 | H32: 154.6057 | I32: 4.2296496e-07
B33: 45503 | C33: 1732.7268 | D33: 5.2655408 | E33: 73.769737 | F33: 1826.6543 | G33: 1818.946 | H33: 167.6352 | I33: 5.4792966e-07
B34: 45503 | C34: 1238.3901 | D34: 5.4771598 | E34: 73.348595 | F34: 1885.9652 | G34: 1877.3545 | H34: 180.01338 | I34: 7.1393365e-07
... B62: 45503 | C62: 0.10000128 | D62: -11.441956 | E62: 61.300064 | F62: 3081.2221 | G62: 3019.9864 | H62: -611.23778 | I62: -0.0026037805
X64: Summary of results
X66: Add in here average values, tables, figures or any result you've got

Sheet Sensor1_60%
D3: Lab-Book
H5: Supervisor: | I5: Johann F. Osma
B8: Experiment Nº: | C8: 5 | H8: Researcher: | I8: =Description!I8 -> Ailin Prado Falla
B9: Title: | C9: EIS for sensor 1 with APAP 15% | H9: Starting Date: | I9: 45504
B11: Description of the experiment
B13: EIS for APAP 60% in sensor 1 using remotly controlled syringe pumps and commercial potentiostat.
B20: Measurement: | L20: Calculation and/or formula:
B21: Date | L21: Date | M21: Description
C22: freq / Hz | D22: neg. Phase / ° | E22: Idc / uA | F22: Z / Ohm | G22: Z' / Ohm | H22: -Z'' / Ohm | I22: Cs / F | M22: Sample 1 | N22: Sample 2 | O22: Sample 3 | P22: Sample 4 | Q22: Sample 5 | R22: Sample 6 | S22: Sample 7 | T22: Sample 8 | U22: Sample 9
B23: 45504 | C23: 50000 | D23: -30.005416 | E23: 7.7819824 | F23: 1376.5026 | G23: 1192.0212 | H23: -688.36398 | I23: -4.6241508e-09
B24: 45504 | C24: 35714.285 | D24: 10.693138 | E24: 7.7819824 | F24: 845.41638 | G24: 830.73575 | H24: 156.86611 | I24: 2.8408549e-08
B25: 45504 | C25: 25641.025 | D25: 14.198756 | E25: 7.7819824 | F25: 1158.3355 | G25: 1122.9492 | H25: 284.12389 | I25: 2.1846255e-08
B26: 45504 | C26: 18390.805 | D26: 26.931108 | E26: 7.5531006 | F26: 1689.7783 | G26: 1506.5248 | H26: 765.33241 | I26: 1.130757e-08
B27: 45504 | C27: 13136.289 | D27: 32.162861 | E27: 7.6446533 | F27: 1970.2213 | G27: 1667.868 | H27: 1048.8033 | I27: 1.1551899e-08
B28: 45504 | C28: 9302.3262 | D28: 37.029912 | E28: 7.8277588 | F28: 2338.6211 | G28: 1866.9708 | H28: 1408.3922 | I28: 1.2148005e-08
B29: 45504 | C29: 6644.5186 | D29: 41.184958 | E29: 7.8277588 | F29: 2865.2313 | G29: 2156.3381 | H29: 1886.7316 | I29: 1.2695403e-08
B30: 45504 | C30: 4761.9048 | D30: 41.981958 | E30: 7.7362061 | F30: 3494.5195 | G30: 2597.6702 | H30: 2337.4721 | I30: 1.4298583e-08
B31: 45504 | C31: 3401.3606 | D31: 40.551118 | E31: 7.6585054 | F31: 4441.4056 | G31: 3374.6965 | H31: 2887.4742 | I31: 1.6205011e-08
B32: 45504 | C32: 2433.8301 | D32: 37.754176 | E32: 0.76035738 | F32: 5281.9096 | G32: 4176.1151 | H32: 3233.9807 | I32: 2.0220526e-08
B33: 45504 | C33: 1732.7268 | D33: 33.503351 | E33: 0.75852633 | F33: 6095.4026 | G33: 5082.673 | H33: 3364.5754 | I33: 2.7299819e-08
B34: 45504 | C34: 1238.3901 | D34: 29.053435 | E34: 0.75394869 | F34: 6828.7648 | G34: 5969.4822 | H34: 3316.2195 | I34: 3.8754253e-08
... B62: 45504 | C62: 0.10000128 | D62: -15.648324 | E62: 0.91142178 | F62: 18415.349 | G62: 17732.791 | H62: -4967.21 | I62: -0.00032040703
L64: Summary of results
L66: Add in here average values, tables, figures or any result you've got

Sheet Sensor2_0%
D3: Lab-Book
H5: Supervisor: | I5: Johann F. Osma
B8: Experiment Nº: | C8: 6 | H8: Researcher: | I8: =Description!I8 -> Ailin Prado Falla
B9: Title: | C9: EIS for sensor 2 with APAP 15% | H9: Starting Date: | I9: 45506
B11: Description of the experiment
B13: EIS for APAP 0% in sensor 2 using remotly controlled syringe pumps and commercial potentiostat.
B20: Measurement: | N20: Calculation and/or formula:
B21: Date | N21: Date | O21: Description
C22: freq / Hz | D22: neg. Phase / ° | E22: Idc / uA | F22: Z / Ohm | G22: Z' / Ohm | H22: -Z'' / Ohm | I22: Cs / F | O22: Sample 1 | P22: Sample 2 | Q22: Sample 3 | R22: Sample 4 | S22: Sample 5 | T22: Sample 6 | U22: Sample 7 | V22: Sample 8 | W22: Sample 9
B23: 45506 | C23: 50000 | D23: 65.218685 | E23: 3.2043457 | F23: 3823.3278 | G23: 1602.5709 | H23: 3471.2537 | I23: 9.1698826e-10
B24: 45506 | C24: 35714.285 | D24: 1.7512645 | E24: 3.2043457 | F24: 1923.8042 | G24: 1922.9056 | H24: 58.792558 | I24: 7.5797663e-08
B25: 45506 | C25: 25641.025 | D25: -4.0555139 | E25: 3.2043457 | F25: 2368.3981 | G25: 2362.4677 | H25: -167.50018 | I25: -3.7056933e-08
B26: 45506 | C26: 18390.805 | D26: 20.495001 | E26: 30.258656 | F26: 1353.3588 | G26: 1267.6949 | H26: 473.84562 | I26: 1.8263438e-08
B27: 45506 | C27: 13136.289 | D27: 42.927892 | E27: 24.857044 | F27: 1860.1396 | G27: 1362.0155 | H27: 1266.899 | I27: 9.5632484e-09
B28: 45506 | C28: 9302.3262 | D28: 47.525612 | E28: 37.491322 | F28: 1845.6489 | G28: 1246.2939 | H28: 1361.3123 | I28: 1.2568134e-08
B29: 45506 | C29: 6644.5186 | D29: 48.908973 | E29: 39.047718 | F29: 2615.04 | G29: 1718.7539 | H29: 1970.8676 | I29: 1.2153438e-08
B30: 45506 | C30: 4761.9048 | D30: 44.758671 | E30: 58.457375 | F30: 2285.8007 | G30: 1623.0987 | H30: 1609.483 | I30: 2.0766009e-08
B31: 45506 | C31: 3401.3606 | D31: 39.138033 | E31: 66.527817 | F31: 2615.4916 | G31: 2028.6474 | H31: 1650.8742 | I31: 2.8343499e-08
B32: 45506 | C32: 2433.8301 | D32: 32.118973 | E32: 78.173492 | F32: 2628.5719 | G32: 2226.2582 | H32: 1397.5567 | I32: 4.6790798e-08
B33: 45506 | C33: 1732.7268 | D33: 25.536823 | E33: 73.751427 | F33: 2981.3635 | G33: 2690.1094 | H33: 1285.2392 | I33: 7.1467084e-08
B34: 45506 | C34: 1238.3901 | D34: 19.791126 | E34: 79.143974 | F34: 2914.9423 | G34: 2742.766 | H34: 986.97671 | I34: 1.3021342e-07
... B62: 45506 | C62: 0.10000128 | D62: -1.6036837 | E62: 215.02863 | F62: 1820.1536 | G62: 1819.4407 | H62: -50.938648 | I62: -0.031244037
N64: Summary of results
N66: Add in here average values, tables, figures or any result you've got

Sheet  Sensor2_15%
D3: Lab-Book
H5: Supervisor: | I5: Johann F. Osma
B8: Experiment Nº: | C8: 7 | H8: Researcher: | I8: =Description!I8 -> Ailin Prado Falla
B9: Title: | C9: EIS for sensor 2 with APAP 15% | H9: Starting Date: | I9: 45505
B11: Description of the experiment
B13: EIS for APAP 15% in sensor 2 using remotly controlled syringe pumps and commercial potentiostat.
B20: Measurement: | L20: Calculation and/or formula:
B21: Date | C21: Description | L21: Date | M21: Description
C22: freq / Hz | D22: neg. Phase / ° | E22: Idc / uA | F22: Z / Ohm | G22: Z' / Ohm | H22: -Z'' / Ohm | I22: Cs / F | M22: Sample 1 | N22: Sample 2 | O22: Sample 3 | P22: Sample 4 | Q22: Sample 5 | R22: Sample 6 | S22: Sample 7 | T22: Sample 8 | U22: Sample 9
B23: 45505 | C23: 50000 | D23: 73.634807 | E23: 9.6130371 | F23: 3627.8733 | G23: 1022.1846 | H23: 3480.8912 | I23: 9.1444941e-10
B24: 45505 | C24: 35714.285 | D24: -1.4281649 | E24: 10.528564 | F24: 2001.8453 | G24: 2001.2235 | H24: -49.893189 | I24: -8.9317572e-08
B25: 45505 | C25: 25641.025 | D25: -19.9677 | E25: 10.528564 | F25: 2100.2961 | G25: 1974.0374 | H25: -717.23083 | I25: -8.6541774e-09
B26: 45505 | C26: 18390.805 | D26: 17.77372 | E26: 10.208368 | F26: 3541.7751 | G26: 3372.7244 | H26: 1081.1572 | I26: 8.0044329e-09
B27: 45505 | C27: 13136.289 | D27: 35.299906 | E27: 10.208368 | F27: 5632.3802 | G27: 4596.8026 | H27: 3254.7063 | I27: 3.7225079e-09
B28: 45505 | C28: 9302.3262 | D28: 41.290105 | E28: 10.391474 | F28: 7477.6717 | G28: 5618.5588 | H28: 4934.3056 | I28: 3.4673887e-09
B29: 45505 | C29: 6644.5186 | D29: 45.319991 | E29: 10.299921 | F29: 10069.608 | G29: 7080.4113 | H29: 7159.943 | I29: 3.3453923e-09
B30: 45505 | C30: 4761.9048 | D30: 41.373209 | E30: 10.208368 | F30: 12629.651 | G30: 9477.5452 | H30: 8347.7071 | I30: 4.0037986e-09
B31: 45505 | C31: 3401.3606 | D31: 33.206769 | E31: 10.057211 | F31: 17644.335 | G31: 14763.008 | H31: 9663.1331 | I31: 4.8422755e-09
B32: 45505 | C32: 2433.8301 | D32: 25.986601 | E32: 1.0075521 | F32: 20158.603 | G32: 18120.499 | H32: 8832.7129 | I32: 7.4034776e-09
B33: 45505 | C33: 1732.7268 | D33: 20.217418 | E33: 0.99656582 | F33: 21456.891 | G33: 20134.889 | H33: 7415.1474 | I33: 1.2387117e-08
B34: 45505 | C34: 1238.3901 | D34: 15.628384 | E34: 0.99290371 | F34: 22525.654 | G34: 21692.863 | H34: 6068.342 | I34: 2.1178373e-08
... B62: 45505 | C62: 0.10000128 | D62: -11.652529 | E62: 0.93051052 | F62: 22153.198 | G62: 21696.632 | H62: -4474.4123 | I62: -0.00035569565
L64: Summary of results
L66: Add in here average values, tables, figures or any result you've got

Sheet Sensor2_30%
D3: Lab-Book
H5: Supervisor: | I5: Johann F. Osma
B8: Experiment Nº: | C8: 8 | H8: Researcher: | I8: =Description!I8 -> Ailin Prado Falla
B9: Title: | C9: EIS for sensor 2 with APAP 15% | H9: Starting Date: | I9: 45503
B11: Description of the experiment
B13: EIS for APAP 30% in sensor 2 using remotly controlled syringe pumps and commercial potentiostat.
B20: Measurement: | L20: Calculation and/or formula:
B21: Date | C21: Description | L21: Date | M21: Description
C22: freq / Hz | D22: neg. Phase / ° | E22: Idc / uA | F22: Z / Ohm | G22: Z' / Ohm | H22: -Z'' / Ohm | I22: Cs / F | M22: Sample 1 | N22: Sample 2 | O22: Sample 3 | P22: Sample 4 | Q22: Sample 5 | R22: Sample 6 | S22: Sample 7 | T22: Sample 8 | U22: Sample 9
B23: 45503 | C23: 50000 | D23: 90.563816 | E23: 129.5495 | F23: 2631.314 | G23: -25.892877 | H23: 2631.1866 | I23: 1.209758e-09
B24: 45503 | C24: 35714.285 | D24: -15.699595 | E24: 132.29608 | F24: 1666.9985 | G24: 1604.8089 | H24: -451.0792 | I24: -9.8792817e-09
B25: 45503 | C25: 25641.025 | D25: -38.268794 | E25: 135.95819 | F25: 1660.4187 | G25: 1303.6177 | H25: -1028.3828 | I25: -6.0357317e-09
B26: 45503 | C26: 18390.805 | D26: -45.375609 | E26: 137.28548 | F26: 1713.0071 | G26: 1203.3123 | H26: -1219.1935 | I26: -7.0981758e-09
B27: 45503 | C27: 13136.289 | D27: -37.746955 | E27: 138.56721 | F27: 1420.4172 | G27: 1123.1553 | H27: -869.54427 | I27: -1.3933356e-08
B28: 45503 | C28: 9302.3262 | D28: -28.997778 | E28: 141.86311 | F28: 1263.4256 | G28: 1105.0407 | H28: -612.47801 | I28: -2.7934318e-08
B29: 45503 | C29: 6644.5186 | D29: -22.160504 | E29: 141.22224 | F29: 1164.7702 | G29: 1078.7296 | H29: -439.35419 | I29: -5.4518242e-08
B30: 45503 | C30: 4761.9048 | D30: -15.876229 | E30: 144.15193 | F30: 1099.9855 | G30: 1058.0264 | H30: -300.91223 | I30: -1.1107072e-07
B31: 45503 | C31: 3401.3606 | D31: -10.897615 | E31: 143.30511 | F31: 1072.654 | G31: 1053.3104 | H31: -202.79013 | I31: -2.307388e-07
B32: 45503 | C32: 2433.8301 | D32: -7.1942844 | E32: 144.71503 | F32: 1059.2358 | G32: 1050.8967 | H32: -132.65262 | I32: -4.9296269e-07
B33: 45503 | C33: 1732.7268 | D33: -4.3413118 | E33: 128.87616 | F33: 1050.2668 | G33: 1047.2534 | H33: -79.502788 | I33: -1.1553343e-06
B34: 45503 | C34: 1238.3901 | D34: -0.16998738 | E34: 144.1474 | F34: 1061.1219 | G34: 1061.1172 | H34: -3.1481736 | I34: -4.0822912e-05
... B62: 45503 | C62: 0.10000128 | D62: -39.491652 | E62: 181.23598 | F62: 1191.5181 | G62: 919.51505 | H62: -757.76474 | I62: -0.0021002944
L64: Summary of results
L66: Add in here average values, tables, figures or any result you've got

Sheet Sensor2_45%
D3: Lab-Book
H5: Supervisor: | I5: Johann F. Osma
B8: Experiment Nº: | C8: 9 | H8: Researcher: | I8: =Description!I8 -> Ailin Prado Falla
B9: Title: | C9: EIS for sensor 2 with APAP 15% | H9: Starting Date: | I9: 45503
B11: Description of the experiment
B13: EIS for APAP 45% in sensor 2 using remotly controlled syringe pumps and commercial potentiostat.
B20: Measurement: | L20: Calculation and/or formula:
B21: Date | C21: Description | L21: Date | M21: Description
C22: freq / Hz | D22: neg. Phase / ° | E22: Idc / uA | F22: Z / Ohm | G22: Z' / Ohm | H22: -Z'' / Ohm | I22: Cs / F | M22: Sample 1 | N22: Sample 2 | O22: Sample 3 | P22: Sample 4 | Q22: Sample 5 | R22: Sample 6 | S22: Sample 7 | T22: Sample 8 | U22: Sample 9
B23: 45503 | C23: 50000 | D23: -52.69645 | E23: 1232.7766 | F23: 331.11511 | G23: 200.66823 | H23: -263.38086 | I23: -1.2085536e-08
B24: 45503 | C24: 35714.285 | D24: -33.695892 | E24: 1301.4412 | F24: 225.20442 | G24: 187.3687 | H24: -124.93998 | I24: -3.5667833e-08
B25: 45503 | C25: 25641.025 | D25: -27.068014 | E25: 1310.5964 | F25: 186.48239 | G25: 166.05641 | H25: -84.858414 | I25: -7.3145874e-08
B26: 45503 | C26: 18390.805 | D26: -20.89739 | E26: 1312.1996 | F26: 179.10359 | G26: 167.32229 | H26: -63.885437 | I26: -1.3546201e-07
B27: 45503 | C27: 13136.289 | D27: -14.548143 | E27: 1320.6224 | F27: 173.26665 | G27: 167.71119 | H27: -43.523439 | I27: -2.7837115e-07
B28: 45503 | C28: 9302.3262 | D28: -10.158505 | E28: 1324.3761 | F28: 173.35711 | G28: 170.6395 | H28: -30.575327 | I28: -5.5957391e-07
B29: 45503 | C29: 6644.5186 | D29: -6.894528 | E29: 1313.8475 | F29: 173.08793 | G29: 171.8363 | H29: -20.777826 | I29: -1.1528067e-06
B30: 45503 | C30: 4761.9048 | D30: -3.9334018 | E30: 1340.3983 | F30: 173.08358 | G30: 172.67588 | H30: -11.872997 | I30: -2.8150042e-06
B31: 45503 | C31: 3401.3606 | D31: -0.80468895 | E31: 1339.4828 | F31: 174.01338 | G31: 173.99622 | H31: -2.4438456 | I31: -1.9146689e-05
B32: 45503 | C32: 2433.8301 | D32: -0.43918326 | E32: 1334.5389 | F32: 175.56372 | G32: 175.55856 | H32: -1.3457168 | I32: -4.8593279e-05
B33: 45503 | C33: 1732.7268 | D33: 0.038640605 | E33: 1331.8839 | F33: 175.91968 | G33: 175.91964 | H33: 0.11864124 | I33: 0.00077420215
B34: 45503 | C34: 1238.3901 | D34: 0.56138589 | E34: 1328.588 | F34: 177.22302 | G34: 177.21451 | H34: 1.7364091 | I34: 7.4013441e-05
... B62: 45503 | C62: 0.10000128 | D62: 30.274356 | E62: 1182.4674 | F62: 239.37548 | G62: 206.72976 | H62: 120.67903 | I62: 0.013188116
L64: Summary of results
L66: Add in here average values, tables, figures or any result you've got

Sheet Sensor2_60%
D3: Lab-Book
H5: Supervisor: | I5: Johann F. Osma
B8: Experiment Nº: | C8: 10 | H8: Researcher: | I8: =Description!I8 -> Ailin Prado Falla
B9: Title: | C9: EIS for sensor 2 with APAP 15% | H9: Starting Date: | I9: 45504
B11: Description of the experiment
B13: EIS for APAP 60% in sensor 2 using remotly controlled syringe pumps and commercial potentiostat.
B20: Measurement: | K20: Calculation and/or formula:
B21: Date | C21: Description | K21: Date | L21: Description
C22: freq / Hz | D22: neg. Phase / ° | E22: Idc / uA | F22: Z / Ohm | G22: Z' / Ohm | H22: -Z'' / Ohm | I22: Cs / F | L22: Sample 1 | M22: Sample 2 | N22: Sample 3 | O22: Sample 4 | P22: Sample 5 | Q22: Sample 6 | R22: Sample 7 | S22: Sample 8 | T22: Sample 9
B23: 45504 | C23: 50000 | D23: 79.011649 | E23: 42.572021 | F23: 3461.7605 | G23: 659.84417 | H23: 3398.2925 | I23: 9.3667596e-10
B24: 45504 | C24: 35714.285 | D24: 1.5297578 | E24: 42.572021 | F24: 1978.1149 | G24: 1977.4099 | H24: 52.808028 | I24: 8.4387519e-08
B25: 45504 | C25: 25641.025 | D25: -22.901528 | E25: 41.656494 | F25: 2627.4749 | G25: 2420.3642 | H25: -1022.4779 | I25: -6.0705885e-09
B26: 45504 | C26: 18390.805 | D26: -33.497423 | E26: 38.864613 | F26: 3948.8197 | G26: 3292.9628 | H26: -2179.3516 | I26: -3.9709289e-09
B27: 45504 | C27: 13136.289 | D27: -24.455124 | E27: 38.040638 | F27: 3554.4024 | G27: 3235.522 | H27: -1471.453 | I27: -8.2338139e-09
B28: 45504 | C28: 9302.3262 | D28: -14.207318 | E28: 38.589954 | F28: 3473.5791 | G28: 3367.3362 | H28: -852.5247 | I28: -2.0068809e-08
B29: 45504 | C29: 6644.5186 | D29: -9.2335859 | E29: 38.498402 | F29: 3537.5104 | G29: 3491.6727 | H29: -567.62823 | I29: -4.2198074e-08
B30: 45504 | C30: 4761.9048 | D30: -5.7956877 | E30: 38.315296 | F30: 3510.8603 | G30: 3492.9139 | H30: -354.53165 | I30: -9.4272367e-08
B31: 45504 | C31: 3401.3606 | D31: -4.8165563 | E31: 38.466476 | F31: 3522.064 | G31: 3509.6264 | H31: -295.73288 | I31: -1.5822235e-07
B32: 45504 | C32: 2433.8301 | D32: -3.67325 | E32: 38.036156 | F32: 3541.135 | G32: 3533.8602 | H32: -226.86777 | I32: -2.8824188e-07
B33: 45504 | C33: 1732.7268 | D33: -2.2288151 | E33: 38.228416 | F33: 3537.3737 | G33: 3534.6977 | H33: -137.56971 | I33: -6.6767822e-07
B34: 45504 | C34: 1238.3901 | D34: -1.1933466 | E34: 38.127708 | F34: 3534.7025 | G34: 3533.9359 | H34: -73.614851 | I34: -1.7458109e-06
... B62: 45504 | C62: 0.10000128 | D62: 0.50096597 | E62: 39.574265 | F62: 3962.0443 | G62: 3961.8928 | H62: 34.641715 | I62: 0.045942558
K64: Summary of results
K66: Add in here average values, tables, figures or any result you've got

Sheet Sensor3_0%
D3: Lab-Book
H5: Supervisor: | I5: Johann F. Osma
B8: Experiment Nº: | C8: 11 | H8: Researcher: | I8: =Description!I8 -> Ailin Prado Falla
B9: Title: | C9: EIS for sensor 3 with APAP 15% | H9: Starting Date: | I9: 45506
B11: Description of the experiment
B13: EIS for APAP 0% in sensor 3 using remotly controlled syringe pumps and commercial potentiostat.
B20: Measurement: | AA20: Calculation and/or formula:
B21: Date | C21: Description | E21: Description | G21: Description | I21: Description | K21: Description | M21: Description | O21: Description | Q21: Description | S21: Description | U21: Description | AA21: Date | AB21: Description
C22: freq / Hz | D22: neg. Phase / ° | E22: Idc / uA | F22: Z / Ohm | G22: Z' / Ohm | H22: -Z'' / Ohm | I22: Cs / F | J22: Current (µA) | K22: Voltage (V) | L22: Current (µA) | M22: Voltage (V) | N22: Current (µA) | O22: Voltage (V) | P22: Current (µA) | Q22: Voltage (V) | R22: Current (µA) | S22: Voltage (V) | T22: Current (µA) | U22: Voltage (V) | V22: Current (µA) | AB22: Sample 1 | AC22: Sample 2 | AD22: Sample 3 | AE22: Sample 4 | AF22: Sample 5 | AG22: Sample 6 | AH22: Sample 7 | AI22: Sample 8 | AJ22: Sample 9
B23: 45506 | C23: 50000 | D23: 69.537327 | E23: 24.261475 | F23: 3733.0939 | G23: 1305.0787 | H23: 3497.5362 | I23: 9.1009747e-10 | J23: 66.308069 | K23: 7.6785371e-05 | L23: 52.584124 | M23: 7.6785371e-05 | N23: 61.840248 | O23: 7.6785371e-05 | P23: 127.54865 | Q23: 7.6785371e-05 | R23: 130.98192 | S23: 7.6785371e-05 | T23: 109.90615 | U23: 7.6785371e-05 | V23: 71.114683
B24: 45506 | C24: 35714.285 | D24: 0.93971355 | E24: 24.261475 | F24: 2122.6399 | G24: 2122.3544 | H24: 34.812058 | I24: 1.2801135e-07 | J24: 68.08424 | K24: 0.010058884 | L24: 53.838396 | M24: 0.010058884 | N24: 62.929726 | O24: 0.010058884 | P24: 129.32477 | Q24: 0.010058884 | R24: 132.70311 | S24: 0.010058884 | T24: 111.26118 | U24: 0.010058884 | V24: 72.506285
B25: 45506 | C25: 25641.025 | D25: -32.36457 | E25: 22.43042 | F25: 2938.1682 | G25: 2481.7506 | H25: -1572.8149 | I25: -3.9464547e-09 | J25: 69.768834 | K25: 0.020041382 | L25: 54.982829 | M25: 0.020041382 | N25: 64.339662 | O25: 0.020041382 | P25: 130.32274 | Q25: 0.020041382 | R25: 134.7631 | S25: 0.020041382 | T25: 112.607 | U25: 0.020041382 | V25: 73.659873
B26: 45506 | C26: 18390.805 | D26: -44.724232 | E26: 21.835566 | F26: 3362.9551 | G26: 2389.386 | H26: -2366.4955 | I26: -3.6569053e-09 | J26: 70.556188 | K26: 0.03002348 | L26: 56.182194 | M26: 0.03002348 | N26: 65.804529 | O26: 0.03002348 | P26: 131.17418 | Q26: 0.03002348 | R26: 135.61454 | S26: 0.03002348 | T26: 114.01691 | U26: 0.03002348 | V26: 74.60289
B27: 45506 | C27: 13136.289 | D27: -20.356374 | E27: 20.920038 | F27: 2524.6317 | G27: 2366.9612 | H27: -878.21404 | I27: -1.3795805e-08 | J27: 68.93568 | K27: 0.040005978 | L27: 57.61044 | M27: 0.040005978 | N27: 67.04967 | O27: 0.040005978 | P27: 131.66857 | Q27: 0.040005978 | R27: 137.7203 | S27: 0.040005978 | T27: 115.43603 | U27: 0.040005978 | V27: 75.408554
B28: 45506 | C28: 9302.3262 | D28: 8.1085202 | E28: 20.553827 | F28: 2805.7717 | G28: 2777.7216 | H28: 395.74976 | I28: 4.3232257e-08 | J28: 70.574498 | K28: 0.049988076 | L28: 58.864737 | M28: 0.049988076 | N28: 68.505383 | O28: 0.049988076 | P28: 132.41014 | Q28: 0.049988076 | R28: 138.8464 | S28: 0.049988076 | T28: 117.15722 | U28: 0.049988076 | V28: 76.672006
B29: 45506 | C29: 6644.5186 | D29: 20.870658 | E29: 19.729853 | F29: 3731.7187 | G29: 3486.8696 | H29: 1329.4603 | I29: 1.8016948e-08 | J29: 72.414732 | K29: 0.059970174 | L29: 60.192275 | M29: 0.059970174 | N29: 69.64066 | O29: 0.059970174 | P29: 133.50883 | Q29: 0.059970174 | R29: 140.84229 | S29: 0.059970174 | T29: 118.29252 | U29: 0.059970174 | V29: 77.203012
B30: 45506 | C30: 4761.9048 | D30: 23.093782 | E30: 18.905878 | F30: 4648.515 | G30: 4276.0019 | H30: 1823.3209 | I30: 1.8330584e-08 | J30: 73.943686 | K30: 0.069952674 | L30: 61.574721 | M30: 0.069952674 | N30: 71.023107 | O30: 0.069952674 | P30: 134.38773 | Q30: 0.069952674 | R30: 142.8565 | S30: 0.069952674 | T30: 119.1165 | U30: 0.069952674 | V30: 78.008699
B31: 45506 | C31: 3401.3606 | D31: 19.418292 | E31: 18.397808 | F31: 5717.1543 | G31: 5391.9429 | H31: 1900.738 | I31: 2.4617571e-08 | J31: 75.078964 | K31: 0.079934768 | L31: 62.691689 | M31: 0.079934768 | N31: 72.195005 | O31: 0.079934768 | P31: 135.08353 | Q31: 0.079934768 | R31: 143.33258 | S31: 0.079934768 | T31: 120.37997 | U31: 0.079934768 | V31: 78.109407
B32: 45506 | C32: 2433.8301 | D32: 15.557618 | E32: 1.7637897 | F32: 6315.3003 | G32: 6083.9154 | H32: 1693.8095 | I32: 3.8606933e-08 | J32: 76.562142 | K32: 0.08991687 | L32: 64.101624 | M32: 0.08991687 | N32: 76.589608 | O32: 0.08991687 | P32: 135.23002 | Q32: 0.08991687 | R32: 144.69671 | S32: 0.08991687 | T32: 121.52438 | U32: 0.08991687 | V32: 78.246737
B33: 45506 | C33: 1732.7268 | D33: 11.840353 | E33: 1.6997028 | F33: 6662.0143 | G33: 6520.2674 | H33: 1366.9482 | I33: 6.7195159e-08 | J33: 78.576326 | K33: 0.099899366 | L33: 65.548182 | M33: 0.099899366 | N33: 77.816439 | O33: 0.099899366 | P33: 135.04691 | Q33: 0.099899366 | R33: 145.29181 | S33: 0.099899366 | T33: 122.61386 | U33: 0.099899366 | V33: 78.107119
B34: 45506 | C34: 1238.3901 | D34: 8.6858978 | E34: 1.6456867 | F34: 6940.052 | G34: 6860.4572 | H34: 1048.0694 | I34: 1.2262319e-07 | J34: 79.555964 | K34: 0.10988147 | L34: 66.765857 | M34: 0.10988147 | N34: 76.745248 | O34: 0.10988147 | P34: 135.55961 | Q34: 0.10988147 | R34: 144.65094 | S34: 0.10988147 | T34: 123.34628 | U34: 0.10988147 | V34: 78.127718
... B62: 45506 | C62: 0.10000128 | D62: 11.950508 | E62: 0.6633091 | F62: 17607.17 | G62: 17225.567 | H62: 3645.8586 | I62: 0.00043653065 | J62: 98.745704 | K62: 0.38938463 | L62: 85.168242 | M62: 0.38938463 | N62: 86.852837 | O62: 0.38938463 | P62: 147.8004 | Q62: 0.38938463 | R62: 156.69031 | S62: 0.38938463 | T62: 130.73473 | U62: 0.38938463 | V62: 101.23596
AA63: Summary of results
AA65: Add in here average values, tables, figures or any result you've got

Sheet Sensor3_15%
D3: Lab-Book
H5: Supervisor: | I5: Johann F. Osma
B8: Experiment Nº: | C8: 12 | H8: Researcher: | I8: =Description!I8 -> Ailin Prado Falla
B9: Title: | C9: EIS for sensor 3 with APAP 15% | H9: Starting Date: | I9: 45505
B11: Description of the experiment
B13: EIS for APAP 15% in sensor 3 using remotly controlled syringe pumps and commercial potentiostat.
B20: Measurement: | Y20: Calculation and/or formula:
B21: Date | C21: Description | E21: Description | G21: Description | I21: Description | K21: Description | M21: Description | O21: Description | Q21: Description | S21: Description | U21: Description | Y21: Date | Z21: Description
C22: freq / Hz | D22: neg. Phase / ° | E22: Idc / uA | F22: Z / Ohm | G22: Z' / Ohm | H22: -Z'' / Ohm | I22: Cs / F | J22: Current (µA) | K22: Voltage (V) | L22: Current (µA) | M22: Voltage (V) | N22: Current (µA) | O22: Voltage (V) | P22: Current (µA) | Q22: Voltage (V) | R22: Current (µA) | S22: Voltage (V) | T22: Current (µA) | U22: Voltage (V) | V22: Current (µA) | Z22: Sample 1 | AA22: Sample 2 | AB22: Sample 3 | AC22: Sample 4 | AD22: Sample 5 | AE22: Sample 6 | AF22: Sample 7 | AG22: Sample 8 | AH22: Sample 9
B23: 45505 | C23: 50000 | D23: 73.634807 | E23: 17.852783 | F23: 3627.8733 | G23: 1022.1846 | H23: 3480.8912 | I23: 9.1444941e-10 | J23: 212.59327 | K23: 7.6785371e-05 | L23: 289.08205 | M23: 7.6785371e-05 | N23: 194.58456 | O23: 7.6785371e-05 | P23: 119.57426 | Q23: 7.6785371e-05 | R23: 124.40834 | S23: 7.6785371e-05 | T23: 180.50356 | U23: 7.6785371e-05 | V23: 167.31977
B24: 45505 | C24: 35714.285 | D24: -2.6171774 | E24: 16.937256 | F24: 2215.6139 | G24: 2213.3028 | H24: -101.17042 | I24: -4.4047839e-08 | J24: 204.17943 | K24: 0.010058884 | L24: 275.71535 | M24: 0.010058884 | N24: 189.75053 | O24: 0.010058884 | P24: 121.61593 | Q24: 0.010058884 | R24: 125.04005 | S24: 0.010058884 | T24: 148.99979 | U24: 0.010058884 | V24: 163.31882
B25: 45505 | C25: 25641.025 | D25: -34.424114 | E25: 16.021729 | F25: 2605.4285 | G25: 2149.1545 | H25: -1472.8858 | I25: -4.2142051e-09 | J25: 202.76952 | K25: 0.020041382 | L25: 271.68679 | M25: 0.020041382 | N25: 145.5482 | O25: 0.020041382 | P25: 123.3829 | Q25: 0.020041382 | R25: 125.54359 | S25: 0.020041382 | T25: 137.69283 | U25: 0.020041382 | V25: 160.84685
B26: 45505 | C26: 18390.805 | D26: -47.040843 | E26: 15.426874 | F26: 2932.5306 | G26: 1998.4517 | H26: -2146.1422 | I26: -4.0323749e-09 | J26: 196.96498 | K26: 0.03002348 | L26: 268.574 | M26: 0.03002348 | N26: 139.34999 | O26: 0.03002348 | P26: 124.78371 | Q26: 0.03002348 | R26: 126.66059 | S26: 0.03002348 | T26: 136.29208 | U26: 0.03002348 | V26: 178.70908
B27: 45505 | C27: 13136.289 | D27: -25.833201 | E27: 14.786005 | F27: 2207.6206 | G27: 1987.0052 | H27: -961.97673 | I27: -1.2594556e-08 | J27: 187.70885 | K27: 0.040005978 | L27: 263.90481 | M27: 0.040005978 | N27: 135.17509 | O27: 0.040005978 | P27: 126.10207 | Q27: 0.040005978 | R27: 127.46625 | S27: 0.040005978 | T27: 135.00113 | U27: 0.040005978 | V27: 175.6237
B28: 45505 | C28: 9302.3262 | D28: -0.51603754 | E28: 15.243769 | F28: 2308.0488 | G28: 2307.9552 | H28: -20.787285 | I28: -8.2305867e-07 | J28: 188.33141 | K28: 0.049988076 | L28: 259.51028 | M28: 0.049988076 | N28: 133.76517 | O28: 0.049988076 | P28: 127.53034 | Q28: 0.049988076 | R28: 128.45502 | S28: 0.049988076 | T28: 134.32364 | U28: 0.049988076 | V28: 163.99176
B29: 45505 | C29: 6644.5186 | D29: 11.312264 | E29: 14.694452 | F29: 2855.8581 | G29: 2800.3765 | H29: 560.19382 | I29: 4.275809e-08 | J29: 183.003 | K29: 0.059970174 | L29: 255.02396 | M29: 0.059970174 | N29: 128.9494 | O29: 0.059970174 | P29: 129.0318 | Q29: 0.059970174 | R29: 130.3319 | S29: 0.059970174 | T29: 135.87089 | U29: 0.059970174 | V29: 149.70474
B30: 45505 | C30: 4761.9048 | D30: 14.211788 | E30: 14.328241 | F30: 3385.9131 | G30: 3282.2867 | H30: 831.26477 | I30: 4.020685e-08 | J30: 170.68896 | K30: 0.069952674 | L30: 250.81253 | M30: 0.069952674 | N30: 127.30145 | O30: 0.069952674 | P30: 129.95653 | Q30: 0.069952674 | R30: 131.97985 | S30: 0.069952674 | T30: 137.07027 | U30: 0.069952674 | V30: 151.92952
B31: 45505 | C31: 3401.3606 | D31: 12.294296 | E31: 14.158845 | F31: 3908.1638 | G31: 3818.537 | H31: 832.17747 | I31: 5.6227853e-08 | J31: 161.82652 | K31: 0.079934768 | L31: 244.77005 | M31: 0.079934768 | N31: 125.9922 | O31: 0.079934768 | P31: 130.515 | Q31: 0.079934768 | R31: 133.45389 | S31: 0.079934768 | T31: 138.6816 | U31: 0.079934768 | V31: 158.86016
B32: 45505 | C32: 2433.8301 | D32: 10.107133 | E32: 1.3481355 | F32: 4202.0415 | G32: 4136.8314 | H32: 737.41328 | I32: 8.867862e-08 | J32: 152.28658 | K32: 0.08991687 | L32: 238.26957 | M32: 0.08991687 | N32: 125.43373 | O32: 0.08991687 | P32: 131.07347 | Q32: 0.08991687 | R32: 133.86588 | S32: 0.08991687 | T32: 139.16688 | U32: 0.08991687 | V32: 149.76884
B33: 45505 | C33: 1732.7268 | D33: 7.7340009 | E33: 1.2977791 | F33: 4377.137 | G33: 4337.3204 | H33: 589.04988 | I33: 1.5593298e-07 | J33: 155.40857 | K33: 0.099899366 | L33: 230.02982 | M33: 0.099899366 | N33: 124.59145 | O33: 0.099899366 | P33: 131.12841 | Q33: 0.099899366 | R33: 134.8455 | S33: 0.099899366 | T33: 139.27674 | U33: 0.099899366 | V33: 145.35594
B34: 45505 | C34: 1238.3901 | D34: 5.5875429 | E34: 1.2620735 | F34: 4485.7352 | G34: 4464.4217 | H34: 436.76042 | I34: 2.9425197e-07 | J34: 148.08421 | K34: 0.10988147 | L34: 217.57841 | M34: 0.10988147 | N34: 124.04213 | O34: 0.10988147 | P34: 130.92928 | Q34: 0.10988147 | R34: 135.12015 | S34: 0.10988147 | T34: 139.38661 | U34: 0.10988147 | V34: 142.92974
... B62: 45505 | C62: 0.10000128 | D62: 16.097745 | E62: 0.8381772 | F62: 12584.769 | G62: 12091.321 | H62: 3489.465 | I62: 0.00045609542 | J62: 104.77915 | K62: 0.38938463 | L62: 103.77202 | M62: 0.38938463 | N62: 97.546339 | O62: 0.38938463 | P62: 102.59099 | Q62: 0.38938463 | R62: 99.478149 | S62: 0.38938463 | T62: 99.560547 | U62: 0.38938463 | V62: 99.82605
Y425: Summary of results
Y427: Add in here average values, tables, figures or any result you've got

Sheet Sensor3_30%
D3: Lab-Book
H5: Supervisor: | I5: Johann F. Osma
B8: Experiment Nº: | C8: 13 | H8: Researcher: | I8: =Description!I8 -> Ailin Prado Falla
B9: Title: | C9: EIS for sensor 3 with APAP 15% | H9: Starting Date: | I9: 45503
B11: Description of the experiment
B13: EIS for APAP 30% in sensor 3 using remotly controlled syringe pumps and commercial potentiostat.
B20: Measurement: | L20: Calculation and/or formula:
B21: Date | C21: Description | L21: Date | M21: Description
C22: freq / Hz | D22: neg. Phase / ° | E22: Idc / uA | F22: Z / Ohm | G22: Z' / Ohm | H22: -Z'' / Ohm | I22: Cs / F | M22: Sample 1 | N22: Sample 2 | O22: Sample 3 | P22: Sample 4 | Q22: Sample 5 | R22: Sample 6 | S22: Sample 7 | T22: Sample 8 | U22: Sample 9
B23: 45503 | C23: 50000 | D23: 77.797649 | E23: 13.275146 | F23: 3720.2912 | G23: 786.33899 | H23: 3636.2395 | I23: 8.7538207e-10
B24: 45503 | C24: 35714.285 | D24: -5.2878755 | E24: 11.444092 | F24: 1971.1725 | G24: 1962.7836 | H24: -181.66302 | I24: -2.4530796e-08
B25: 45503 | C25: 25641.025 | D25: -38.095618 | E25: 10.528564 | F25: 2250.8822 | G25: 1771.4043 | H25: -1388.7396 | I25: -4.4695512e-09
B26: 45503 | C26: 18390.805 | D26: -48.11189 | E26: 9.9337101 | F26: 2390.3534 | G26: 1595.9865 | H26: -1779.4988 | I26: -4.8631951e-09
B27: 45503 | C27: 13136.289 | D27: -27.188012 | E27: 9.1097355 | F27: 1822.4863 | G27: 1621.1234 | H27: -832.71554 | I27: -1.454959e-08
B28: 45503 | C28: 9302.3262 | D28: -3.9457087 | E28: 9.292841 | F28: 1887.2684 | G28: 1882.795 | H28: -129.86518 | I28: -1.3174551e-07
B29: 45503 | C29: 6644.5186 | D29: 7.6988277 | E29: 8.2857609 | F29: 2250.289 | G29: 2230.0048 | H29: 301.46201 | I29: 7.945551e-08
B30: 45503 | C30: 4761.9048 | D30: 11.651414 | E30: 7.5531006 | F30: 2597.2363 | G30: 2543.7188 | H30: 524.5297 | I30: 6.3719057e-08
B31: 45503 | C31: 3401.3606 | D31: 11.190142 | E31: 6.9901466 | F31: 2942.9471 | G31: 2886.9974 | H31: 571.12472 | I31: 8.1928782e-08
B32: 45503 | C32: 2433.8301 | D32: 10.286107 | E32: 0.64866066 | F32: 3157.9432 | G32: 3107.1898 | H32: 563.89385 | I32: 1.1596649e-07
B33: 45503 | C33: 1732.7268 | D33: 8.8768741 | E33: 0.60379982 | F33: 3308.9788 | G33: 3269.3446 | H33: 510.61385 | I33: 1.7988603e-07
B34: 45503 | C34: 1238.3901 | D34: 7.4884705 | E34: 0.56443214 | F34: 3422.8565 | G34: 3393.6634 | H34: 446.08954 | I34: 2.8809824e-07
... B62: 45503 | C62: 0.10000128 | D62: 16.638001 | E62: 0.32181263 | F62: 12054.99 | G62: 11550.282 | H62: 3451.6318 | I62: 0.00046109467
L425: Summary of results
L427: Add in here average values, tables, figures or any result you've got

Sheet Sensor3_45%
D3: Lab-Book
H5: Supervisor: | I5: Johann F. Osma
B8: Experiment Nº: | C8: 14 | H8: Researcher: | I8: =Description!I8 -> Ailin Prado Falla
B9: Title: | C9: EIS for sensor 3 with APAP 15% | H9: Starting Date: | I9: 45503
B11: Description of the experiment
B13: EIS for APAP 45% in sensor 3 using remotly controlled syringe pumps and commercial potentiostat.
B20: Measurement: | K20: Calculation and/or formula:
B21: Date | C21: Description | K21: Date | L21: Description
C22: freq / Hz | D22: neg. Phase / ° | E22: Idc / uA | F22: Z / Ohm | G22: Z' / Ohm | H22: -Z'' / Ohm | I22: Cs / F | L22: Sample 1 | M22: Sample 2 | N22: Sample 3 | O22: Sample 4 | P22: Sample 5 | Q22: Sample 6 | R22: Sample 7 | S22: Sample 8 | T22: Sample 9
B23: 45503 | C23: 50000 | D23: -83.686578 | E23: 104.83026 | F23: 1915.4906 | G23: 210.64103 | H23: -1903.8736 | I23: -1.6719066e-09
B24: 45503 | C24: 35714.285 | D24: -23.875831 | E24: 100.25262 | F24: 1248.418 | G24: 1141.5844 | H24: -505.30455 | I24: -8.8191141e-09
B25: 45503 | C25: 25641.025 | D25: -34.820886 | E25: 97.506042 | F25: 994.15989 | G25: 816.14673 | H25: -567.67808 | I25: -1.0934089e-08
B26: 45503 | C26: 18390.805 | D26: -18.711983 | E26: 95.811371 | F26: 967.979 | G26: 916.81472 | H26: -310.5384 | I26: -2.786789e-08
B27: 45503 | C27: 13136.289 | D27: 0.33503235 | E27: 92.42392 | F27: 1049.7928 | G27: 1049.7749 | H27: 6.1385421 | I27: 1.9737048e-06
B28: 45503 | C28: 9302.3262 | D28: 10.323066 | E28: 92.057709 | F28: 1252.2958 | G28: 1232.0249 | H28: 224.40926 | I28: 7.624086e-08
B29: 45503 | C29: 6644.5186 | D29: 14.848006 | E29: 84.275482 | F29: 1485.8175 | G29: 1436.2046 | H29: 380.74924 | I29: 6.2909693e-08
B30: 45503 | C30: 4761.9048 | D30: 17.040022 | E30: 80.247162 | F30: 1721.6162 | G30: 1646.0377 | H30: 504.50178 | I30: 6.6248603e-08
B31: 45503 | C31: 3401.3606 | D31: 18.096541 | E31: 78.677032 | F31: 1932.3511 | G31: 1836.7663 | H31: 600.22503 | I31: 7.7956684e-08
B32: 45503 | C32: 2433.8301 | D32: 17.990101 | E32: 80.407402 | F32: 2099.6219 | G32: 1996.9711 | H32: 648.47384 | I32: 1.0084106e-07
B33: 45503 | C33: 1732.7268 | D33: 17.708159 | E33: 77.798126 | F33: 2317.1692 | G33: 2207.3775 | H33: 704.81038 | I33: 1.30322e-07
B34: 45503 | C34: 1238.3901 | D34: 16.576863 | E34: 74.282455 | F34: 2541.0358 | G34: 2435.4249 | H34: 724.96097 | I34: 1.7727521e-07
... B62: 45503 | C62: 0.10000128 | D62: 13.478135 | E62: 13.118334 | F62: 8064.6179 | G62: 7842.5097 | H62: 1879.655 | I62: 0.00084671336
K64: Summary of results
K66: Add in here average values, tables, figures or any result you've got

Sheet Sensor3_60%
D3: Lab-Book
H5: Supervisor: | I5: Johann F. Osma
B8: Experiment Nº: | C8: 15 | H8: Researcher: | I8: =Description!I8 -> Ailin Prado Falla
B9: Title: | C9: EIS for sensor 3 with APAP 15% | H9: Starting Date: | I9: 45504
B11: Description of the experiment
B13: EIS for APAP 60% in sensor 3 using remotly controlled syringe pumps and commercial potentiostat.
B20: Measurement: | K20: Calculation and/or formula:
B21: Date | C21: Description | K21: Date | L21: Description
C22: freq / Hz | D22: neg. Phase / ° | E22: Idc / uA | F22: Z / Ohm | G22: Z' / Ohm | H22: -Z'' / Ohm | I22: Cs / F | L22: Sample 1 | M22: Sample 2 | N22: Sample 3 | O22: Sample 4 | P22: Sample 5 | Q22: Sample 6 | R22: Sample 7 | S22: Sample 8 | T22: Sample 9
B23: 45504 | C23: 50000 | D23: -54.280643 | E23: 2.2888184 | F23: 1302.6033 | G23: 760.48003 | H23: -1057.5658 | I23: -3.0098353e-09
B24: 45504 | C24: 35714.285 | D24: -12.168528 | E24: 2.2888184 | F24: 819.67297 | G24: 801.25642 | H24: -172.77713 | I24: -2.5792409e-08
B25: 45504 | C25: 25641.025 | D25: -12.569094 | E25: 2.2888184 | F25: 806.2533 | G25: 786.93087 | H25: -175.45425 | I25: -3.5376988e-08
B26: 45504 | C26: 18390.805 | D26: -0.72370388 | E26: 2.3345947 | F26: 917.31258 | G26: 917.23941 | H26: -11.586281 | I26: -7.4692213e-07
B27: 45504 | C27: 13136.289 | D27: 11.772228 | E27: 2.3345947 | F27: 975.35667 | G27: 954.8414 | H27: 198.99378 | I27: 6.0884665e-08
B28: 45504 | C28: 9302.3262 | D28: 21.827864 | E28: 2.6092529 | F28: 1121.3617 | G28: 1040.9658 | H28: 416.94394 | I28: 4.1034666e-08
B29: 45504 | C29: 6644.5186 | D29: 28.393201 | E29: 2.5177002 | F29: 1339.2281 | G29: 1178.1257 | H29: 636.82952 | I29: 3.7612606e-08
B30: 45504 | C30: 4761.9048 | D30: 31.01931 | E30: 2.4261475 | F30: 1606.7979 | G30: 1377.0156 | H30: 828.0262 | I30: 4.0364107e-08
B31: 45504 | C31: 3401.3606 | D31: 30.867996 | E31: 2.3758411 | F31: 1941.6358 | G31: 1666.6063 | H31: 996.17934 | I31: 4.6971013e-08
B32: 45504 | C32: 2433.8301 | D32: 28.151487 | E32: 2.3391962 | F32: 2256.2263 | G32: 1989.3221 | H32: 1064.4975 | I32: 6.1430668e-08
B33: 45504 | C33: 1732.7268 | D33: 24.777917 | E33: 2.3025751 | F33: 2519.1988 | G33: 2287.279 | H33: 1055.8017 | I33: 8.6997682e-08
B34: 45504 | C34: 1238.3901 | D34: 21.800761 | E34: 0.22842646 | F34: 2737.5061 | G34: 2541.7221 | H34: 1016.6555 | I34: 1.2641216e-07
... B62: 45504 | C62: 0.10000128 | D62: -10.9462 | E62: 1.1842537 | F62: 10458.421 | G62: 10268.14 | H62: -1985.9201 | I62: -0.00080140636
K64: Summary of results
K66: Add in here average values, tables, figures or any result you've got

Sheet Sensor4_0%
D3: Lab-Book
H5: Supervisor: | I5: Johann F. Osma
B8: Experiment Nº: | C8: 16 | H8: Researcher: | I8: =Description!I8 -> Ailin Prado Falla
B9: Title: | C9: EIS for sensor 4 with APAP 15% | H9: Starting Date: | I9: 45506
B11: Description of the experiment
B13: EIS for APAP 0% in sensor 4 using remotly controlled syringe pumps and commercial potentiostat.
B20: Measurement: | N20: Calculation and/or formula:
B21: Date | C21: Description | N21: Date | O21: Description
C22: freq / Hz | D22: neg. Phase / ° | E22: Idc / uA | F22: Z / Ohm | G22: Z' / Ohm | H22: -Z'' / Ohm | I22: Cs / F | O22: Sample 1 | P22: Sample 2 | Q22: Sample 3 | R22: Sample 4 | S22: Sample 5 | T22: Sample 6 | U22: Sample 7 | V22: Sample 8 | W22: Sample 9
B23: 45506 | C23: 50000 | D23: 61.00556 | E23: 5.9509277 | F23: 4865.1488 | G23: 2358.258 | H23: 4255.3839 | I23: 7.4801685e-10
B24: 45506 | C24: 35714.285 | D24: 13.712262 | E24: 5.9509277 | F24: 2353.2823 | G24: 2286.21 | H24: 557.83631 | I24: 7.9886132e-09
B25: 45506 | C25: 25641.025 | D25: -13.447514 | E25: 6.8664551 | F25: 4007.2737 | G25: 3897.4077 | H25: -931.90966 | I25: -6.6605628e-09
B26: 45506 | C26: 18390.805 | D26: -45.093852 | E26: 6.4544678 | F26: 12408.528 | G26: 8759.7704 | H26: -8788.5149 | I26: -9.8469993e-10
B27: 45506 | C27: 13136.289 | D27: -35.1765 | E27: 6.5460205 | F27: 8399.3641 | G27: 6865.4827 | H27: -4838.8494 | I27: -2.5038328e-09
B28: 45506 | C28: 9302.3262 | D28: -9.1848775 | E28: 6.9122314 | F28: 6432.1066 | G28: 6349.6369 | H28: -1026.697 | I28: -1.666427e-08
B29: 45506 | C29: 6644.5186 | D29: 22.716225 | E29: 7.0037842 | F29: 7057.9586 | G29: 6510.464 | H29: 2725.5526 | I29: 8.7882427e-09
B30: 45506 | C30: 4761.9048 | D30: 39.23465 | E30: 7.0953369 | F30: 9607.8127 | G30: 7441.8478 | H30: 6076.9207 | I30: 5.4999134e-09
B31: 45506 | C31: 3401.3606 | D31: 41.836223 | E31: 7.2922945 | F31: 15130.354 | G31: 11272.937 | H31: 10092.001 | I31: 4.6364991e-09
B32: 45506 | C32: 2433.8301 | D32: 40.019251 | E32: 0.75303316 | F32: 19911.651 | G32: 15248.908 | H32: 12804.087 | I32: 5.1071812e-09
B33: 45506 | C33: 1732.7268 | D33: 36.560831 | E33: 0.77225924 | F33: 23986.253 | G33: 19266.355 | H33: 14288.033 | I33: 6.4286177e-09
B34: 45506 | C34: 1238.3901 | D34: 32.662969 | E34: 0.79240084 | F34: 27787.346 | G34: 23393.048 | H34: 14996.728 | I34: 8.5697099e-09
... B62: 45506 | C62: 0.10000128 | D62: -4.442631 | E62: 1.8613415 | F62: 11444.023 | G62: 11409.638 | H62: -886.46394 | I62: -0.001795368
N64: Summary of results
N66: Add in here average values, tables, figures or any result you've got

Sheet Sensor4_15%
D3: Lab-Book
H5: Supervisor: | I5: Johann F. Osma
B8: Experiment Nº: | C8: 17 | H8: Researcher: | I8: =Description!I8 -> Ailin Prado Falla
B9: Title: | C9: EIS for sensor 4 with APAP 15% | H9: Starting Date: | I9: 45505
B11: Description of the experiment
B13: EIS for APAP 15% in sensor 4 using remotly controlled syringe pumps and commercial potentiostat.
B20: Measurement: | L20: Calculation and/or formula:
B21: Date | C21: Description | L21: Date | M21: Description
C22: freq / Hz | D22: neg. Phase / ° | E22: Idc / uA | F22: Z / Ohm | G22: Z' / Ohm | H22: -Z'' / Ohm | I22: Cs / F | M22: Sample 1 | N22: Sample 2 | O22: Sample 3 | P22: Sample 4 | Q22: Sample 5 | R22: Sample 6 | S22: Sample 7 | T22: Sample 8 | U22: Sample 9
B23: 45505 | C23: 50000 | D23: 62.787803 | E23: 13.275146 | F23: 4105.5071 | G23: 1877.3961 | H23: 3651.1057 | I23: 8.7181778e-10
B24: 45505 | C24: 35714.285 | D24: 9.0169978 | E24: 13.275146 | F24: 2359.4136 | G24: 2330.2558 | H24: 369.78494 | I24: 1.2051163e-08
B25: 45505 | C25: 25641.025 | D25: -21.720334 | E25: 14.190674 | F25: 3856.0478 | G25: 3582.2733 | H25: -1427.0326 | I25: -4.3496154e-09
B26: 45505 | C26: 18390.805 | D26: -47.711706 | E26: 13.96203 | F26: 7579.7566 | G26: 5100.1255 | H26: -5607.2658 | I26: -1.5433636e-09
B27: 45505 | C27: 13136.289 | D27: -28.698475 | E27: 14.053583 | F27: 4920.8718 | G27: 4316.3867 | H27: -2363.0034 | I27: -5.1272335e-09
B28: 45505 | C28: 9302.3262 | D28: 9.7042406 | E28: 14.511347 | F28: 4601.4524 | G28: 4535.6102 | H28: 775.63156 | I28: 2.2058354e-08
B29: 45505 | C29: 6644.5186 | D29: 31.426127 | E29: 14.6029 | F29: 6551.2097 | G29: 5590.2332 | H29: 3415.7929 | I29: 7.0123743e-09
B30: 45505 | C30: 4761.9048 | D30: 36.929681 | E30: 14.6029 | F30: 8814.9023 | G30: 7046.3994 | H30: 5296.2965 | I30: 6.3105488e-09
B31: 45505 | C31: 3401.3606 | D31: 34.127145 | E31: 14.67154 | F31: 12557.456 | G31: 10394.994 | H31: 7045.125 | I31: 6.6416923e-09
B32: 45505 | C32: 2433.8301 | D32: 30.052782 | E32: 1.4598298 | F32: 15200.416 | G32: 13156.94 | H32: 7612.3319 | I32: 8.5903758e-09
B33: 45505 | C33: 1732.7268 | D33: 25.780996 | E33: 1.4570832 | F33: 17201.597 | G33: 15489.403 | H33: 7481.5328 | I33: 1.2277203e-08
B34: 45505 | C34: 1238.3901 | D34: 21.525627 | E34: 1.4579988 | F34: 18940.938 | G34: 17619.875 | H34: 6949.7588 | I34: 1.8492385e-08
... B62: 45505 | C62: 0.10000128 | D62: -3.8255029 | E62: 1.6213779 | F62: 12878.391 | G62: 12849.696 | H62: -859.22081 | I62: -0.0018522934
L64: Summary of results
L66: Add in here average values, tables, figures or any result you've got

Sheet Sensor4_30%
D3: Lab-Book
H5: Supervisor: | I5: Johann F. Osma
B8: Experiment Nº: | C8: 18 | H8: Researcher: | I8: =Description!I8 -> Ailin Prado Falla
B9: Title: | C9: EIS for sensor 4 with APAP 15% | H9: Starting Date: | I9: 45505
B11: Description of the experiment
B13: EIS for APAP 30% in sensor 4 using remotly controlled syringe pumps and commercial potentiostat.
B20: Measurement: | L20: Calculation and/or formula:
B21: Date | C21: Description | L21: Date | M21: Description
C22: freq / Hz | D22: neg. Phase / ° | E22: Idc / uA | F22: Z / Ohm | G22: Z' / Ohm | H22: -Z'' / Ohm | I22: Cs / F | M22: Sample 1 | N22: Sample 2 | O22: Sample 3 | P22: Sample 4 | Q22: Sample 5 | R22: Sample 6 | S22: Sample 7 | T22: Sample 8 | U22: Sample 9
B23: 45505 | C23: 50000 | D23: 89.583637 | E23: 6.8664551 | F23: 3237.9367 | G23: 23.529581 | H23: 3237.8512 | I23: 9.8308991e-10
B24: 45505 | C24: 35714.285 | D24: -6.6487722 | E24: 6.8664551 | F24: 1622.7715 | G24: 1611.8577 | H24: -187.88887 | I24: -2.3717948e-08
B25: 45505 | C25: 25641.025 | D25: -21.330496 | E25: 6.8664551 | F25: 1627.0893 | G25: 1515.63 | H25: -591.84897 | I25: -1.0487545e-08
B26: 45505 | C26: 18390.805 | D26: -4.1385352 | E26: 7.5531006 | F26: 2020.1747 | G26: 2014.907 | H26: -145.79252 | I26: -5.935867e-08
B27: 45505 | C27: 13136.289 | D27: 18.405539 | E27: 7.9195499 | F27: 2229.6153 | G27: 2115.5604 | H27: 703.98044 | I27: 1.7210237e-08
B28: 45505 | C28: 9302.3262 | D28: 34.836173 | E28: 8.5604191 | F28: 2749.4497 | G28: 2256.7173 | H28: 1570.5733 | I28: 1.0893573e-08
B29: 45505 | C29: 6644.5186 | D29: 45.965449 | E29: 8.92663 | F29: 3576.4817 | G29: 2485.9839 | H29: 2571.207 | I29: 9.3157876e-09
B30: 45505 | C30: 4761.9048 | D30: 52.03628 | E30: 9.2012882 | F30: 4659.9074 | G30: 2866.5997 | H30: 3673.873 | I30: 9.0973579e-09
B31: 45505 | C31: 3401.3606 | D31: 54.641653 | E31: 9.7093105 | F31: 6533.1369 | G31: 3780.6508 | H31: 5328.0914 | I31: 8.7820477e-09
B32: 45505 | C32: 2433.8301 | D32: 53.457352 | E32: 1.056993 | F32: 8624.096 | G32: 5134.9676 | H32: 6928.7185 | I32: 9.4379345e-09
B33: 45505 | C33: 1732.7268 | D33: 48.961958 | E33: 1.1540389 | F33: 10910.308 | G33: 7163.2718 | H33: 8229.36 | I33: 1.1161536e-08
B34: 45505 | C34: 1238.3901 | D34: 42.622672 | E34: 1.2877083 | F34: 13161.355 | G34: 9684.5089 | H34: 8912.4376 | I34: 1.4420029e-08
... B62: 45505 | C62: 0.10000128 | D62: -2.9641328 | E62: 5.8205532 | F62: 3055.2347 | G62: 3051.1471 | H62: -157.98864 | I62: -0.010073693
L64: Summary of results
L66: Add in here average values, tables, figures or any result you've got

Sheet Sensor4_45%
D3: Lab-Book
H5: Supervisor: | I5: Johann F. Osma
B8: Experiment Nº: | C8: 19 | H8: Researcher: | I8: =Description!I8 -> Ailin Prado Falla
B9: Title: | C9: EIS for sensor 4 with APAP 15% | H9: Starting Date: | I9: 45505
B11: Description of the experiment
B13: EIS for APAP 45% in sensor 4 using remotly controlled syringe pumps and commercial potentiostat.
B20: Measurement: | K20: Calculation and/or formula:
B21: Date | C21: Description | K21: Date | L21: Description
C22: freq / Hz | D22: neg. Phase / ° | E22: Idc / uA | F22: Z / Ohm | G22: Z' / Ohm | H22: -Z'' / Ohm | I22: Cs / F | L22: Sample 1 | M22: Sample 2 | N22: Sample 3 | O22: Sample 4 | P22: Sample 5 | Q22: Sample 6 | R22: Sample 7 | S22: Sample 8 | T22: Sample 9
B23: 45505 | C23: 50000 | D23: 89.583637 | E23: 20.599365 | F23: 3237.9367 | G23: 23.529581 | H23: 3237.8512 | I23: 9.8308991e-10
B24: 45505 | C24: 35714.285 | D24: -7.3703803 | E24: 21.514893 | F24: 1624.9007 | G24: 1611.4751 | H24: -208.44701 | I24: -2.1378759e-08
B25: 45505 | C25: 25641.025 | D25: -19.987939 | E25: 21.514893 | F25: 1666.4865 | G25: 1566.1051 | H25: -569.64231 | I25: -1.0896387e-08
B26: 45505 | C26: 18390.805 | D26: 0.014988749 | E26: 22.842646 | F26: 2364.2785 | G26: 2364.2784 | H26: 0.61850238 | I26: 1.3991943e-05
B27: 45505 | C27: 13136.289 | D27: 15.864239 | E27: 23.391962 | F27: 2853.4864 | G27: 2744.8031 | H27: 780.02591 | I27: 1.5532394e-08
B28: 45505 | C28: 9302.3262 | D28: 25.590007 | E28: 24.216175 | F28: 3494.1391 | G28: 3151.3916 | H28: 1509.2181 | I28: 1.1336437e-08
B29: 45505 | C29: 6644.5186 | D29: 29.473816 | E29: 24.582386 | F29: 4328.714 | G29: 3768.4946 | H29: 2129.8388 | I29: 1.1246306e-08
B30: 45505 | C30: 4761.9048 | D30: 29.650237 | E30: 24.948597 | F30: 5110.8091 | G30: 4441.6075 | H30: 2528.338 | I30: 1.3219173e-08
B31: 45505 | C31: 3401.3606 | D31: 26.252575 | E31: 25.246048 | F31: 6238.1376 | G31: 5594.6916 | H31: 2759.3092 | I31: 1.6957706e-08
B32: 45505 | C32: 2433.8301 | D32: 21.838609 | E32: 25.529861 | F32: 7070.813 | G32: 6563.3787 | H32: 2630.2959 | I32: 2.4861382e-08
B33: 45505 | C33: 1732.7268 | D33: 17.487351 | E33: 25.667191 | F33: 7505.8697 | G33: 7158.9732 | H33: 2255.4781 | I33: 4.0724093e-08
B34: 45505 | C34: 1238.3901 | D34: 13.727938 | E34: 25.859474 | F34: 7825.9002 | G34: 7602.3418 | H34: 1857.1788 | I34: 6.920045e-08
... B62: 45505 | C62: 0.10000128 | D62: 2.0442827 | E62: 33.907082 | F62: 6657.8004 | G62: 6653.563 | H62: 237.49636 | I62: 0.0067012776
K64: Summary of results
K66: Add in here average values, tables, figures or any result you've got

Sheet Sensor4_60%
D3: Lab-Book
H5: Supervisor: | I5: Johann F. Osma
B8: Experiment Nº: | C8: 20 | H8: Researcher: | I8: =Description!I8 -> Ailin Prado Falla
B9: Title: | C9: EIS for sensor 4 with APAP 15% | H9: Starting Date: | I9: 45504
B11: Description of the experiment
B13: EIS for APAP 60% in sensor 4 using remotly controlled syringe pumps and commercial potentiostat.
B20: Measurement: | K20: Calculation and/or formula:
B21: Date | C21: Description | K21: Date | L21: Description
C22: freq / Hz | D22: neg. Phase / ° | E22: Idc / uA | F22: Z / Ohm | G22: Z' / Ohm | H22: -Z'' / Ohm | I22: Cs / F | L22: Sample 1 | M22: Sample 2 | N22: Sample 3 | O22: Sample 4 | P22: Sample 5 | Q22: Sample 6 | R22: Sample 7 | S22: Sample 8 | T22: Sample 9
B23: 45504 | C23: 50000 | D23: -72.869363 | E23: 6.8664551 | F23: 2274.5481 | G23: 669.97123 | H23: -2173.6392 | I23: -1.4644099e-09
B24: 45504 | C24: 35714.285 | D24: -9.5932236 | E24: 6.8664551 | F24: 1199.9274 | G24: 1183.1473 | H24: -199.97046 | I24: -2.2284984e-08
B25: 45504 | C25: 25641.025 | D25: -11.027468 | E25: 6.8664551 | F25: 1229.2614 | G25: 1206.5638 | H25: -235.13259 | I25: -2.6398054e-08
B26: 45504 | C26: 18390.805 | D26: 7.1474017 | E26: 7.2784424 | F26: 1637.3187 | G26: 1624.5956 | H26: 203.71913 | I26: 4.2480301e-08
B27: 45504 | C27: 13136.289 | D27: 21.708195 | E27: 7.3699951 | F27: 1897.7167 | G27: 1763.1301 | H27: 701.9268 | I27: 1.7260589e-08
B28: 45504 | C28: 9302.3262 | D28: 32.616461 | E28: 7.7362061 | F28: 2310.9641 | G28: 1946.5195 | H28: 1245.6392 | I28: 1.3735241e-08
B29: 45504 | C29: 6644.5186 | D29: 39.379175 | E29: 7.8277588 | F29: 2928.3191 | G29: 2263.4859 | H29: 1857.8709 | I29: 1.2892617e-08
B30: 45504 | C30: 4761.9048 | D30: 41.502503 | E30: 7.9195499 | F30: 3666.0414 | G30: 2745.5965 | H30: 2429.3125 | I30: 1.3758023e-08
